Workbook

Sheet Test Releases
A1: Test Release ID(PK) | B1: Upstream Release ID | C1: Test Run IDs | D1: Test Case IDs
A2: TEST_RELEASE_ID-
A3: TEST_RELEASE_ID-
A4: TEST_RELEASE_ID-
A5: TEST_RELEASE_ID-
A6: TEST_RELEASE_ID-
A7: TEST_RELEASE_ID-
A8: TEST_RELEASE_ID-
A9: TEST_RELEASE_ID-
A10: TEST_RELEASE_ID-
A11: TEST_RELEASE_ID-
A12: TEST_RELEASE_ID-
A13: TEST_RELEASE_ID-
... A21: TEST_RELEASE_ID-
A25: Test Run ID(PK) | B25: 모델명 | C25: 대상 일련번호
B26: HRK-9000A | C26: 9HA09A24I0014
B27: HLM-9000 | C27: 9LM00024D0014
B28: HTR 상세모델명(TBD) | C28: TBD
B29: HDR-9000_OP | C29: TBD
B30: HDR-9000_JUNCTION_BOX | C30: TBD
B31: HDR-9000_? | C31: TBD
B32: HDC-9100 | C32: PP #1(관리번호 L-062)
B33: MR30G | C33: 2232318003141
B34: MR30G | C34: Wi-Fi Band 분리설정
B35: MR30G | C35: Wi-Fi Channel 설정
B36: MR30G | C36: Channel Bandwidth 설정
B37: MR30G | C37: Wi-Fi 규격 ( Mode ) 설정
B38: MR30G | C38: Wi-Fi Security
B39: Lens
B40: 모델아이
B41: Junction Box Power Cable
B42: HDC Power Cable
B43: HLM Power Cable : L-form Power Cable
B44: OP Signal and Power Cable
B45: HDR Signal and Power Cable
A49: TC IDs | B49: Defects ID | C49: Validation ID | D49: Test Release Date

Sheet Test Runs
A1: 구분 | B1: 날짜 | C1: ID | D1: 테스트 항목 | E1: 기대결과 | F1: 문제점 | G1: 문제점 절차 | H1: 첨부파일(사진)
A2: 문제점 관리 | B2: 46113 | C2: HRK-003 | D2: 측정 Data 전송 | E2: Data 전송이 잘 되어야 함 | F2: -. HIIS 데이터 전송 값 삭제가 안됨 | G2: -. HRK->HIIS->Refraction 데이터 삭제 안됨 (검토)
A3: 문제점 관리 | B3: 46113 | C3: HRK-010 | D3: =IFERROR(INDEX('HRK 테스트'!B:B,MATCH(TRIM(CLEAN(C3)),'HRK 테스트'!A:A,0)), IFERROR(INDEX('HLM 테스트'!B:B,MATCH(TRIM(CLEAN(C3)),'HLM 테스트'!A:A,0)), IFERROR(INDEX('HTR 테스트'!B:B,MATCH(TRIM(CLEAN(C3)),'HTR 테스트'!A:A,0)), IFERROR(INDEX('HDR 테스트'!B:B,MATCH(TRIM(CLEAN(C3)),'HDR 테스트'!A:A,0)), IFERROR(INDEX('HDC 테스트'!B:B,MATCH(TRIM(CLEAN(C3)),'HDC 테스트'!A:A,0)),""))))) -> Server 재연결 시 복구 | E3: =IFERROR(INDEX('HRK 테스트'!D:D,MATCH(TRIM(CLEAN(C3)),'HRK 테스트'!A:A,0)), IFERROR(INDEX('HLM 테스트'!D:D,MATCH(TRIM(CLEAN(C3)),'HLM 테스트'!A:A,0)), IFERROR(INDEX('HTR 테스트'!D:D,MATCH(TRIM(CLEAN(C3)),'HTR 테스트'!A:A,0)), IFERROR(INDEX('HDR 테스트'!D:D,MATCH(TRIM(CLEAN(C3)),'HDR 테스트'!A:A,0)), IFERROR(INDEX('HDC 테스트'!D:D,MATCH(TRIM(CLEAN(C3)),'HDC 테스트'!A:A,0)),""))))) -> 1. Server 접속상태 표시 2. Server와의 접속상태를 갱신하고, 데이터 전송 성공 3. 데이터 전송 실패시 에러메세지 확인( DR(Server)와 끊어짐 상태 표시 또는 전송실패 표시 ) 4. 실패 이후 재전송 성공 | F3: -. AP 재부팅 시 재 연결 안됨 | G3: -. AP 재부팅 시, HDR에서 HRK와 자동 연결이 안되고, HRK에서 재시도를 하면 연결됨
A4: 문제점 관리 | B4: 46113 | C4: HRK-011 | D4: =IFERROR(INDEX('HRK 테스트'!B:B,MATCH(TRIM(CLEAN(C4)),'HRK 테스트'!A:A,0)), IFERROR(INDEX('HLM 테스트'!B:B,MATCH(TRIM(CLEAN(C4)),'HLM 테스트'!A:A,0)), IFERROR(INDEX('HTR 테스트'!B:B,MATCH(TRIM(CLEAN(C4)),'HTR 테스트'!A:A,0)), IFERROR(INDEX('HDR 테스트'!B:B,MATCH(TRIM(CLEAN(C4)),'HDR 테스트'!A:A,0)), IFERROR(INDEX('HDC 테스트'!B:B,MATCH(TRIM(CLEAN(C4)),'HDC 테스트'!A:A,0)),""))))) -> 장비 재부팅 시 복구 | E4: =IFERROR(INDEX('HRK 테스트'!D:D,MATCH(TRIM(CLEAN(C4)),'HRK 테스트'!A:A,0)), IFERROR(INDEX('HLM 테스트'!D:D,MATCH(TRIM(CLEAN(C4)),'HLM 테스트'!A:A,0)), IFERROR(INDEX('HTR 테스트'!D:D,MATCH(TRIM(CLEAN(C4)),'HTR 테스트'!A:A,0)), IFERROR(INDEX('HDR 테스트'!D:D,MATCH(TRIM(CLEAN(C4)),'HDR 테스트'!A:A,0)), IFERROR(INDEX('HDC 테스트'!D:D,MATCH(TRIM(CLEAN(C4)),'HDC 테스트'!A:A,0)),""))))) -> 1. 데이터 전송 성공 2. 데이터 전송 실패시 에러메세지 확인( DR(Server)와 끊어짐 상태 표시 또는 전송실패 표시 ) 3. 실패 이후 재전송 성공 | F4: -. 양산버전이 재부팅 시 연결안됨 | G4: -. 제품 1분정도 OFF 후 재부팅 시 연결X (양산품, CCD 변경품으로 테스트) - 제품별 연결성 차이 검토
A5: 문제점 관리 | B5: 46148 | C5: HRK-001 | D5: =IFERROR(INDEX('HRK 테스트'!B:B,MATCH(TRIM(CLEAN(C5)),'HRK 테스트'!A:A,0)), IFERROR(INDEX('HLM 테스트'!B:B,MATCH(TRIM(CLEAN(C5)),'HLM 테스트'!A:A,0)), IFERROR(INDEX('HTR 테스트'!B:B,MATCH(TRIM(CLEAN(C5)),'HTR 테스트'!A:A,0)), IFERROR(INDEX('HDR 테스트'!B:B,MATCH(TRIM(CLEAN(C5)),'HDR 테스트'!A:A,0)), IFERROR(INDEX('HDC 테스트'!B:B,MATCH(TRIM(CLEAN(C5)),'HDC 테스트'!A:A,0)),""))))) -> AP 연결 및 인증 확인 | E5: =IFERROR(INDEX('HRK 테스트'!D:D,MATCH(TRIM(CLEAN(C5)),'HRK 테스트'!A:A,0)), IFERROR(INDEX('HLM 테스트'!D:D,MATCH(TRIM(CLEAN(C5)),'HLM 테스트'!A:A,0)), IFERROR(INDEX('HTR 테스트'!D:D,MATCH(TRIM(CLEAN(C5)),'HTR 테스트'!A:A,0)), IFERROR(INDEX('HDR 테스트'!D:D,MATCH(TRIM(CLEAN(C5)),'HDR 테스트'!A:A,0)), IFERROR(INDEX('HDC 테스트'!D:D,MATCH(TRIM(CLEAN(C5)),'HDC 테스트'!A:A,0)),""))))) -> 1. 연결 가능한 AP 목록 (SSID/RSSI 순서) 2. AP 연결 성공 3. AP 인증 성공 | F5: =IFERROR(INDEX('Test Cases'!K:K,MATCH(TRIM(CLEAN(C5)),'Test Cases'!A:A,0)),"") -> SETUP MODE 화면 진입 위해 "홈 화면 우측 하단 톱니바퀴 아이콘 터치" 시 간헐적 미인식
A6: 시나리오 & TC 정합성 협의사항(특이사항) | C6: HRK-002 | F6: =IFERROR(INDEX('Test Cases'!K:K,MATCH(TRIM(CLEAN(C6)),'Test Cases'!A:A,0)),"") -> 0
A7: 시나리오 & TC 정합성 협의사항(특이사항) | C7: HRK-003 | F7: =IFERROR(INDEX('Test Cases'!K:K,MATCH(TRIM(CLEAN(C7)),'Test Cases'!A:A,0)),"") -> 0
A8: 시나리오 & TC 정합성 협의사항(특이사항) | C8: HRK-004 | F8: =IFERROR(INDEX('Test Cases'!K:K,MATCH(TRIM(CLEAN(C8)),'Test Cases'!A:A,0)),"") -> 0
A9: 시나리오 & TC 정합성 협의사항(특이사항) | C9: HRK-005 | F9: =IFERROR(INDEX('Test Cases'!K:K,MATCH(TRIM(CLEAN(C9)),'Test Cases'!A:A,0)),"") -> 0
A10: 시나리오 & TC 정합성 협의사항(특이사항) | C10: HRK-006 | F10: =IFERROR(INDEX('Test Cases'!K:K,MATCH(TRIM(CLEAN(C10)),'Test Cases'!A:A,0)),"") -> 0
A11: 시나리오 & TC 정합성 협의사항(특이사항) | C11: HRK-007 | F11: =IFERROR(INDEX('Test Cases'!K:K,MATCH(TRIM(CLEAN(C11)),'Test Cases'!A:A,0)),"") -> 0
A12: 시나리오 & TC 정합성 협의사항(특이사항) | C12: HRK-008 | F12: =IFERROR(INDEX('Test Cases'!K:K,MATCH(TRIM(CLEAN(C12)),'Test Cases'!A:A,0)),"") -> 0
A13: 시나리오 & TC 정합성 협의사항(특이사항) | C13: HRK-009 | F13: =IFERROR(INDEX('Test Cases'!K:K,MATCH(TRIM(CLEAN(C13)),'Test Cases'!A:A,0)),"") -> 0
A14: 시나리오 & TC 정합성 협의사항(특이사항) | C14: HRK-010 | F14: =IFERROR(INDEX('Test Cases'!K:K,MATCH(TRIM(CLEAN(C14)),'Test Cases'!A:A,0)),"") -> -. HRK-9000A CCD 타입은 AP끊었을 시, 아이콘 갱신이 다소 오래걸림(Ver26) -. AP 재부팅 시, HDR에서 HRK와 자동 연결이 안되고, HRK에서 재시도를 하면 연결됨
A15: 시나리오 & TC 정합성 협의사항(특이사항) | C15: HRK-011 | F15: =IFERROR(INDEX('Test Cases'!K:K,MATCH(TRIM(CLEAN(C15)),'Test Cases'!A:A,0)),"") -> 0
A16: 시나리오 & TC 정합성 협의사항(특이사항) | C16: HRK-012 | F16: =IFERROR(INDEX('Test Cases'!K:K,MATCH(TRIM(CLEAN(C16)),'Test Cases'!A:A,0)),"")

Sheet Test Cases
A1: Test Senario ID | B1: 테스트 항목 | C1: 테스트 절차 | D1: 기대 결과 | E1: Test Case ID(PK) | F1: Test Config ID | G1: Test Procedure | H1: Test Procedure Actual Result(재현 판단 기준) | I1: 비고 | J1: 결과 판정 | K1: 특이사항
A2: HRK-001 | B2: AP 연결 및 인증 확인 | C2: 1. 사용자 설정에서 WIFI - BAND를 2.4GHz / 5GHz 선택한다. 2. AP SSID 스캔을 위해 SCAN버튼을 touch한다. 3. AP List 모달(팝업)에서 사용할 AP를 터치. 4. AP 의 ID/Password 를 입력하고, Verify 버튼을 touch한다. 5. 인증 확인 메시지를 확인한다. - 성공시: AP Password is okay! - 실패시: Error code 확인 | D2: 1. 연결 가능한 AP 목록 (SSID/RSSI 순서) 2. AP 연결 성공 3. AP 인증 성공 | E2: TC-HRK-001-WIFI-001 | F2: 테스트대상 구성 (장비 대수, S/W Version): - HRK-9000A (1대, 1.01.01A) 테스트환경 구성 : - AP(2.4GHz Band) 1대 | G2: 1. SETUP MODE 화면으로 진입(홈 화면 우측 하단 톱니바퀴 아이콘 터치) 2. SETUP MODE 화면-2 페이지-WIFI 탭 으로이동 3. BAND 항목을 2.4GHz로 터치 4. SCAN 버튼 터치. | H2: AP List에 SETUP 화면에 RSSI 신호강도가 강한 순에서 작은 순으로 SSID가 배치확인 | I2: 2.4GHz, 5GHz AP 에서 각각 수행 연결 실패시, 에러메세지 확인 최초 연결 후 AP 끊어지는 경우 체크 필요 | J2: 1. HDR / 1) 1대 / 2) 2대 / 2. HIIS / 3. MATE / | K2: SETUP MODE 화면 진입 위해 "홈 화면 우측 하단 톱니바퀴 아이콘 터치" 시 간헐적 미인식
G3: 1. AP List 모달(팝업)에서 사용할 AP를 터치. | H3: SETUP MODE 화면-2 페이지-WIFI 탭 의 AP SSID 항목에 선택한 SSID 가 시현
G4: 1. AP Password 입력 2. Verify 버튼 터치 3. AP Password is okay! 모달 시현 대기 4. AP Password is okay! 모달 OK 버튼 터치 | H4: 최초 연결 후 TBD 초 간 AP 끊어짐 없고, 연결관련 에러메세지 없이, 측정화면의 우측상단 Wi-Fi & HDR 정상연결 상태확인(아래의 범례와 같은 상태) 범례 *Wi-Fi 아이콘(정상 연결상태): 파란색으로 RSSI 신호세기 표기, 우하단심볼 미표기
A5: HRK-002 | B5: Server 연결 확인 | C5: 1. AP를 연결한다. 2. 사용자 설정에서 HDR IP / Port 를 입력한다. (port (default: 42000)) 3. 사용자 설정을 나와서 HDR(Server) 연결을 확인한다. 4. 오른쪽 위 상단의 ICON 확인 - 제품 4대 연결 가능. (HDR / HRK-Mate / HIIS) - 연결 성공 O, 연결 실패 X로 icon 위에 표시 (모두 연결시 O/X 표시 안함.) | D5: 1. DR 연결 성공 | E5: TC-HRK-002-WIFI-001 | F5: 테스트대상 구성 (장비 대수, S/W Version): - HRK-9000A (1대, 1.01.01A) 테스트환경 구성 : - AP(2.4GHz Band) 1대 - HDR-9000 1대 | G5: 1. AP 연결 및 인증 확인(HRK-001) 2. SETUP MODE 화면으로 진입(홈 화면 우측 하단 톱니바퀴 아이콘 터치) 3. SETUP MODE 화면-2 페이지-HDR IP 1탭으로 이동 4. HDR Nickname 입력 ex> HDR9000_1(연결할 Nickname) 5. HDR IP 입력 ex> 192.168.***.***(연결할 HDR IP) 6. HDR Port 입력 ex> 42000(연결할 Port) 7. HDR 연결할 항목에 대한 Checkbox를 터치(V 표기 시현되도록) | H5: 홈 화면의 우측상단 Wi-Fi & HDR 정상연결 상태확인(아래의 범례와 같은 상태) 범례 *Wi-Fi 아이콘 : 회색으로 RSSI 신호세기 표기상태, 좌상단심볼 미표기 *DR 아이콘 : 회색으로 DR 표기, 좌상단심볼 미표기 | I5: 최소 1개, 최대4개 늘려가면서 연결 시도 이후 모든 전송 테스트도 Server 개수 늘려가면서 진행 | J5: 1. HDR / 1) 1대 / 합 2) 2대 / 2. HIIS / 3. MATE /
A6: HRK-003 | B6: 측정데이터 전송(수동모드) | C6: 1. AP를 연결한다. 2. HDR(Server)을 연결한다. 3. 사용자 설정에서 TRANSFER TYPE(전송모드)를 수동(Manual)으로 설정한다. 4. REF / KER 측정 모드에서 데이터를 측정한다. 5. 프린트 버튼을 누르거나, 화면에 프린트 버튼을 touch 한다. 6. HDR network connect 팝업창에서 HDR (server) 버튼을 touch하여, 데이터를 전송한다. 7. HDR( Server )에서 데이터를 수신 확인한다. 8. 전송 이후, AP 또는 Server 연결이 끊어지는지 확인한다. | D6: 1. 데이터 전송 성공 2. 데이터 전송 실패시 에러메세지 확인( DR(Server)와 끊어짐 상태 표시 또는 전송실패 표시 ) 3. 실패 이후 재전송 성공 | E6: TC-HRK-003-WIFI-001 | F6: 테스트대상 구성 (장비 대수, S/W Version): - HRK-9000A (1대, 1.01.01A) 테스트환경 구성 : - AP(2.4GHz Band) 1대 - HDR-9000 1대 | G6: 1. AP 연결 및 인증 확인(HRK-001) 2. Server 연결 확인(HRK-002, HDR에 연결) 3. SETUP MODE 화면으로 진입(홈 화면 우측 하단 톱니바퀴 아이콘 터치) 4. SETUP MODE 화면-2 페이지-WIFI 탭으로 이동 5. TRANSFER TYPE를 Manual으로 설정. 6. "REF/KER 측정 MODE 화면"으로 이동(SETUP MODE 화면에서 좌측상단 홈 아이콘 터치) 7. 모델아이 장착 8. 조이스틱 수동조작하여 모델아이의 눈동자를 화면 위치로 대략적 배치 9. "REF/KER 측정 MODE 화면"의 중간상단의 MEASURE 아이콘을 터치 | H6: HRK가 "REF/KER 측정 MODE 화면"에서 모델아이 측정한 상태로 멈춤 확인 | I6: 측정 모드는 모드별로 테스트 진행 | J6: 1. HDR / 1) 1대 / 합 2) 2대 / 2. HIIS / 3. MATE /
G7: 1. "REF/KER 측정 MODE 화면"의 우측하단의 프린터 아이콘을 터치. 2. HDR network connect 팝업창에서 HDR (server) 아이콘을 터치. | H7: "REF/KER 측정 MODE 화면"의 HDR network connect 팝업창에서 HDR (server) 아이콘이 문서교환 아이콘으로 변경시현확인
G8: 1. HDR network connect 팝업창에서 OK 버튼 터치 | H8: HRK가 움직이며 ALIGN CENTER 비모달 시현 후 동공의 CENTER에서 멈춤
G9: 1. OP 키보드의 LOAD 버튼 클릭 2. OP Basic Operation 화면 좌측상단 LOAD DATA의 RK 버튼 터치 | H9: "REF/KER 측정 MODE 화면" 좌측상단 차트번호와 OP Basic Operation 화면 좌측상단 LOAD DATA의 차트번호 비교결과, 측정화면 차트번호가 1이 더 큰지 확인
G10: 1. OP Basic Operation 화면 좌측상단 LOAD DATA의 차트번호 터치 | H10: "REF/KER 측정 MODE 화면"의 중간단의 좌우 R, L 데이터 목록과 OP Basic Operation 화면 상단중간 데이터 비교결과, S(SPH), C(CYLINDER), A(TBD)의 수치가 일치 상태확인(TBD. STEP 디옵터 설정 의존성 확인)
A11: HRK-004 | B11: 측정데이터 전송(자동모드) | C11: 1. AP를 연결한다. 2. HDR(Server)을 연결한다. 3. 사용자 설정에서 TRANSFER TYPE(전송모드)를 자동(Auto)으로 설정한다. 4. REF / KER 측정 모드에서 데이터를 측정한다. 5. 프린트 버튼을 누르거나, 화면에 프린트 버튼을 touch 한다. 6. HDR (Server) 가 모두 연결된 경우, 팝업창이 뜨지 않고 데이터가 전송되는지 확인한다. - 1대 이상 연결된 경우, 모두 연결된 상태확인 - 여러대 중 1~2대 연결이 끊어진 상태확인 (전송모드가 자동이어도, HDR network connect 팝업창이 떠야 정상) 7. HDR( Server )에서 데이터를 수신 확인한다. 8. 전송 이후, AP 또는 Server 연결이 끊어지는지 확인한다. | D11: 1. 데이터 전송 성공 2. 데이터 전송 실패시 에러메세지 확인( DR(Server)와 끊어짐 상태 표시 또는 전송실패 표시 ) 3. 실패 이후 재전송 성공 | E11: TC-HRK-004-WIFI-001 | F11: 테스트대상 구성 (장비 대수, S/W Version): - HRK-9000A (1대, 1.01.01A) 테스트환경 구성 : - AP(2.4GHz Band) 1대 - HDR-9000 1대 | G11: 1. AP 연결 및 인증 확인(HRK-001) 2. Server 연결 확인(HRK-002, HDR에 연결) 3. SETUP MODE 화면으로 진입(홈 화면 우측 하단 톱니바퀴 아이콘 터치) 4. SETUP MODE 화면-2 페이지-WIFI 탭으로 이동 5. TRANSFER TYPE를 Auto로 설정. 6. "REF/KER 측정 MODE 화면"으로 이동(SETUP MODE 화면에서 좌측상단 홈 아이콘 터치) 7. 모델아이 장착 8. 조이스틱 수동조작하여 모델아이의 눈동자를 화면 위치로 대략적 배치 9. "REF/KER 측정 MODE 화면"의 중간상단의 MEASURE 아이콘을 터치 | H11: HRK가 "REF/KER 측정 MODE 화면"에서 모델아이 측정한 상태로 멈춤 확인 | I11: 측정 모드는 모드별로 테스트 진행 | J11: 1. HDR / 1) 1대 / 합 2) 2대 / 2. HIIS / 3. MATE /
G12: 1. "REF/KER 측정 MODE 화면"의 우측하단의 프린터 아이콘을 터치. | H12: "REF/KER 측정 MODE 화면"의 HDR network connect 팝업창이 뜨지 않고, HRK가 움직이며 ALIGN CENTER 비모달 시현 후 동공의 CENTER에서 멈춤
G13: 1. OP 키보드의 LOAD 버튼 클릭 2. OP Basic Operation 화면 좌측상단 LOAD DATA의 RK 버튼 터치 | H13: "REF/KER 측정 MODE 화면" 좌측상단 차트번호와 OP Basic Operation 화면 좌측상단 LOAD DATA의 차트번호 비교결과, 측정화면 차트번호가 1이 더 큰지 확인 TBD - 1대 이상 연결된 경우, 모두 연결된 상태확인 - 여러대 중 1~2대 연결이 끊어진 상태확인 (전송모드가 자동이어도, HDR network connect 팝업창이 떠야 정상)
G14: 1. OP Basic Operation 화면 좌측상단 LOAD DATA의 차트번호 터치 | H14: "REF/KER 측정 MODE 화면"의 중간단의 좌우 R, L 데이터 목록과 OP Basic Operation 화면 상단중간 데이터 비교결과, S(SPH), C(CYLINDER), A(TBD)의 수치가 일치 상태확인(TBD. STEP 디옵터 설정 의존성 확인)
A15: HRK-005 | B15: 이미지(IOL) 촬영 후 전송 | C15: 1. RETRO-ILLUMINATION MODE에 들어간다. 2. 이미지를 촬영한다. - 조이스틱 누르거나, 화면에 CAPTURE touch - 최소1장 ~ 최대4장 capture, OD/OS 무관 3. 프린트 버튼을 눌러 데이터를 전송한다. - Image Transmitting (1/4) : 캡쳐한 이미지 4장중 1장 전송중 - Image Transfer Successful! : 이미지 전송 성공 - Image Transfer Failed! : 이미지 전송 실패 4. 전송이 완료 되면, HDR( Server )에서 데이터를 수신 확인한다. 5. 전송 이후, AP 또는 Server 연결이 끊어지는지 확인한다. | D15: 1. 데이터 전송 성공 2. 데이터 전송 실패시 에러메세지 확인( DR(Server)와 끊어짐 상태 표시 또는 전송실패 표시 ) 3. 실패 이후 재전송 성공 4. HDR이 Server 목록에 있더라도 전송 성공 하는지 유무 | E15: TC-HRK-005-WIFI-001 | F15: 테스트대상 구성 (장비 대수, S/W Version): - HRK-9000A (1대, 1.01.01A) 테스트환경 구성 : - AP(2.4GHz Band) 1대 - HDR-9000 1대 | G15: 1. "REF/KER 측정 MODE 화면"의 좌측하단 부기기능 아이콘(2x2 Matrix 아이콘, 우상단, 좌하단 2개 파란색, 나머지 2개 회색) 터치 2. Retro-ILL 터치 3. HRK 동작 멈출 때까지 대기 4. 조이스틱의 Shot 버튼 누름 | H15: RETRO-ILLUMINATION MODE 화면 하단중간 Image Captured 시현확인 | I15: 같은 환자번호에서, 여러 번 보냈을때 이미지가 덮어쓰여지는지 확인 필요. | J15: 1. HDR / 전송 기능 없음 1) 1대 / 2) 2대 / 2. HIIS / 3. MATE /
G16: 1. "REF/KER 측정 MODE 화면"으로 이동(좌측상단의 홈 아이콘 터치) 2. "REF/KER 측정 MODE 화면"의 우측하단의 프린터 아이콘을 터치. | H16: "REF/KER 측정 MODE 화면" 좌측상단 차트번호와 OP Basic Operation 화면 좌측상단 LOAD DATA의 차트번호 비교결과, 측정화면 차트번호가 1이 더 큰지 확인 TBD - HDR( Server )에서 데이터를 수신 확인한다. (OP 어디에서 수신이미지 확인하기 위한 위치 공유요청) TBD - Patient ID가 동일한 마이봄샘 이미지가 저장되어 있었다면, 덮어씀 (덮어쓰는 이미지 전 후 비교방법 공유요청) TBD - 같은 환자번호에서, 여러 번 보냈을때 이미지가 덮어쓰여지는지 확인 필요. (같은 환자번호에서, 여러 번 보내는 방법 공유요청)
A17: HRK-006 | B17: 이미지( COLOR ) 촬영 후 전송 | C17: 1. COLOR VIEW MODE에 들어간다. 2. 이미지를 촬영한다. - 조이스틱 누르거나, 화면에 CAPTURE touch - 최소1장 ~ 최대4장 capture, OD/OS 무관 3. 프린트 버튼을 눌러 데이터를 전송한다. - Image Transmitting (1/4) : 캡쳐한 이미지 4장중 1장 전송중 - Image Transfer Successful! : 이미지 전송 성공 - Image Transfer Failed! : 이미지 전송 실패 4. 전송이 완료 되면, HDR( Server )에서 데이터를 수신 확인한다. 5. 전송 이후, AP 또는 Server 연결이 끊어지는지 확인한다. | D17: 1. 데이터 전송 성공 2. 데이터 전송 실패시 에러메세지 확인( DR(Server)와 끊어짐 상태 표시 또는 전송실패 표시 ) 3. 실패 이후 재전송 성공 4. HDR이 Server 목록에 있더라도 전송 성공 하는지 유무 | E17: TC-HRK-006-WIFI-001 | F17: 테스트대상 구성 (장비 대수, S/W Version): - HRK-9000A (1대, 1.01.01A) 테스트환경 구성 : - AP(2.4GHz Band) 1대 - HDR-9000 1대 | G17: 1. "REF/KER 측정 MODE 화면"의 좌측하단 부기기능 아이콘(2x2 Matrix 아이콘, 우상단, 좌하단 2개 파란색, 나머지 2개 회색) 터치 2. COLOR 터치 3. HRK 동작 멈출 때까지 대기 4. 조이스틱의 Shot 버튼 누름 | H17: COLOR VIEW MODE 화면 하단중간 Image Captured 시현확인 | I17: 같은 환자번호에서, 여러 번 보냈을때 이미지가 덮어쓰여지는지 확인 필요. | J17: 1. HDR / 전송 기능 없음 1) 1대 / 2) 2대 / 2. HIIS / 3. MATE /
G18: 1. "REF/KER 측정 MODE 화면"으로 이동(좌측상단의 홈 아이콘 터치) 2. "REF/KER 측정 MODE 화면"의 우측하단의 프린터 아이콘을 터치. 3. HRK 동작 멈출 때까지 대기 | H18: "REF/KER 측정 MODE 화면" 좌측상단 차트번호와 OP Basic Operation 화면 좌측상단 LOAD DATA의 차트번호 비교결과, 측정화면 차트번호가 1이 더 큰지 확인 TBD - HDR( Server )에서 데이터를 수신 확인한다. (OP 어디에서 수신이미지 확인하기 위한 위치 공유요청) TBD - Patient ID가 동일한 마이봄샘 이미지가 저장되어 있었다면, 덮어씀 (덮어쓰는 이미지 전 후 비교방법 공유요청) TBD - 같은 환자번호에서, 여러 번 보냈을때 이미지가 덮어쓰여지는지 확인 필요. (같은 환자번호에서, 여러 번 보내는 방법 공유요청)
A19: HRK-007 | B19: 이미지( TFBUT ) 촬영 후 전송 | C19: 1. TFBUT MODE에 들어간다. 2. 이미지를 촬영한다. - 조이스틱 누르거나, 화면에 CAPTURE touch - 최소1장 ~ 최대4장 capture, OD/OS 무관 3. 프린트 버튼을 눌러 데이터를 전송한다. - Image Transmitting (1/4) : 캡쳐한 이미지 4장중 1장 전송중 - Image Transfer Successful! : 이미지 전송 성공 - Image Transfer Failed! : 이미지 전송 실패 4. 전송이 완료 되면, HDR( Server )에서 데이터를 수신 확인한다. 5. 전송 이후, AP 또는 Server 연결이 끊어지는지 확인한다. | D19: 1. 데이터 전송 성공 2. 데이터 전송 실패시 에러메세지 확인( DR(Server)와 끊어짐 상태 표시 또는 전송실패 표시 ) 3. 실패 이후 재전송 성공 4. HDR이 Server 목록에 있더라도 전송 성공 하는지 유무 | E19: TC-HRK-007-WIFI-001 | F19: 테스트대상 구성 (장비 대수, S/W Version): - HRK-9000A (1대, 1.01.01A) 테스트환경 구성 : - AP(2.4GHz Band) 1대 - HDR-9000 1대 | G19: 1. "REF/KER 측정 MODE 화면"의 좌측하단 부기기능 아이콘(2x2 Matrix 아이콘, 우상단, 좌하단 2개 파란색, 나머지 2개 회색) 터치 2. TFBUT 터치 3. HRK 동작 멈출 때까지 대기 4. 조이스틱의 Shot 버튼 누름 | H19: TFBUT MODE 화면 하단중간 Image Captured 시현확인 | I19: 같은 환자번호에서, 여러 번 보냈을때 이미지가 덮어쓰여지는지 확인 필요. Server 가 HIIS-1인 경우, duration time 출력 여부 확인 필요. | J19: 1. HDR / 전송 기능 없음 1) 1대 / 2) 2대 / 2. HIIS / 3. MATE /
G20: 1. "REF/KER 측정 MODE 화면"으로 이동(좌측상단의 홈 아이콘 터치) 2. "REF/KER 측정 MODE 화면"의 우측하단의 프린터 아이콘을 터치. 3. HRK 동작 멈출 때까지 대기 | H20: "REF/KER 측정 MODE 화면" 좌측상단 차트번호와 OP Basic Operation 화면 좌측상단 LOAD DATA의 차트번호 비교결과, 측정화면 차트번호가 1이 더 큰지 확인 TBD - HDR( Server )에서 데이터를 수신 확인한다. (OP 어디에서 수신이미지 확인하기 위한 위치 공유요청) TBD - Patient ID가 동일한 마이봄샘 이미지가 저장되어 있었다면, 덮어씀 (덮어쓰는 이미지 전 후 비교방법 공유요청) TBD - 같은 환자번호에서, 여러 번 보냈을때 이미지가 덮어쓰여지는지 확인 필요. (같은 환자번호에서, 여러 번 보내는 방법 공유요청)
A21: HRK-008 | B21: 이미지( MEIBO ) 촬영 후 전송 | C21: 1. MEIBOGRAPHY MODE에 들어간다. 2. 이미지를 촬영한다. - 조이스틱 누르거나, 화면에 CAPTURE touch - 최소1장 ~ 최대4장 capture, OD/OS 무관 3. 프린트 버튼을 눌러 데이터를 전송한다. - Image Transmitting (1/4) : 캡쳐한 이미지 4장중 1장 전송중 - Image Transfer Successful! : 이미지 전송 성공 - Image Transfer Failed! : 이미지 전송 실패 4. 전송이 완료 되면, HDR( Server )에서 데이터를 수신 확인한다. 5. 전송 이후, AP 또는 Server 연결이 끊어지는지 확인한다. | D21: 1. 데이터 전송 성공 2. 데이터 전송 실패시 에러메세지 확인( DR(Server)와 끊어짐 상태 표시 또는 전송실패 표시 ) 3. 실패 이후 재전송 성공 4. HDR이 Server 목록에 있더라도 전송 성공 하는지 유무 | E21: TC-HRK-008-WIFI-001 | F21: 테스트대상 구성 (장비 대수, S/W Version): - HRK-9000A (1대, 1.01.01A) 테스트환경 구성 : - AP(2.4GHz Band) 1대 - HDR-9000 1대 | G21: 1. "REF/KER 측정 MODE 화면"의 좌측하단 부기기능 아이콘(2x2 Matrix 아이콘, 우상단, 좌하단 2개 파란색, 나머지 2개 회색) 터치 2. MEIBO 터치 3. HRK 동작 멈출 때까지 대기 4. 조이스틱의 Shot 버튼 누름 | H21: MEIBOGRAPHY MODE 화면의 하단중간 Image Captured 시현확인 | I21: 같은 환자번호에서, 여러 번 보냈을때 이미지가 덮어쓰여지는지 확인 필요. | J21: 1. HDR / 전송 기능 없음 1) 1대 / 2) 2대 / 2. HIIS / 3. MATE /
G22: 1. "REF/KER 측정 MODE 화면"으로 이동(좌측상단의 홈 아이콘 터치) 2. "REF/KER 측정 MODE 화면"의 우측하단의 프린터 아이콘을 터치 3. HRK 동작 멈출 때까지 대기 | H22: "REF/KER 측정 MODE 화면" 좌측상단 차트번호와 OP Basic Operation 화면 좌측상단 LOAD DATA의 차트번호 비교결과, 측정화면 차트번호가 1이 더 큰지 확인 TBD - HDR( Server )에서 데이터를 수신 확인한다. (OP 어디에서 수신이미지 확인하기 위한 위치 공유요청) TBD - Patient ID가 동일한 마이봄샘 이미지가 저장되어 있었다면, 덮어씀 (덮어쓰는 이미지 전 후 비교방법 공유요청) TBD - 같은 환자번호에서, 여러 번 보냈을때 이미지가 덮어쓰여지는지 확인 필요. (같은 환자번호에서, 여러 번 보내는 방법 공유요청)
A23: HRK-009 | B23: 이미지( MEIBO - 강조 ) 전송 | C23: 1. MEIBOGRAPHY MODE에 들어간다. 2. 이미지를 촬영한다. 3. 눈 모양 버튼을 touch하여 이미지 display 화면으로 들어가서 마이봄샘을 강조할 이미지 1장을 선택한다. 4. 아이콘 버튼을 touch하여 마이봄샘을 강조한다. 5. 프린트 버튼을 눌러 데이터를 전송한다. - Image Transmitting (1/1) : 캡쳐한 이미지 1장 전송중 - Image Transfer Successful! : 이미지 전송 성공 - Image Transfer Failed! : 이미지 전송 실패 6. 전송이 완료 되면, HDR( Server )에서 데이터를 수신 확인한다. (Patient ID가 동일한 마이봄샘 이미지가 저장되어 있었다면, 덮어씀) 7. 전송 이후, AP 또는 Server 연결이 끊어지는지 확인한다. | D23: 1. 데이터 전송 성공 2. 데이터 전송 실패시 에러메세지 확인( DR(Server)와 끊어짐 상태 표시 또는 전송실패 표시 ) 3. 실패 이후 재전송 성공 4. HDR이 Server 목록에 있더라도 전송 성공 하는지 유무 | E23: TC-HRK-009-WIFI-001 | F23: 테스트대상 구성 (장비 대수, S/W Version): - HRK-9000A (1대, 1.01.01A) 테스트환경 구성 : - AP(2.4GHz Band) 1대 - HDR-9000 1대 | G23: 1. "REF/KER 측정 MODE 화면"의 좌측하단 부기기능 아이콘(2x2 Matrix 아이콘, 우상단, 좌하단 2개 파란색, 나머지 2개 회색) 터치 2. MEIBO 터치 3. HRK 동작 멈출 때까지 대기 4. 조이스틱의 Shot 아이콘 누름 | H23: MEIBOGRAPHY MODE 화면의 하단중간 Image Captured 시현확인 | I23: 같은 환자번호에서, 여러 번 보냈을때 이미지가 덮어쓰여지는지 확인 필요. | J23: 1. HDR / 전송 기능 없음 1) 1대 / 2) 2대 / 2. HIIS / 3. MATE /
G24: 1. MEIBOGRAPHY 화면의 우측하단 이중 사각형 안 눈모양 아이콘을 터치 | H24: "MEIBOGRAPHY MODE 이미지 시현화면"으로 화면전환 확인 (4개의 이미지가 한 화면에 4분할 되어 시현)
G25: 1. MEIBOGRAPHY MODE 이미지 시현화면의 4장 중 마이봄샘을 강조할 이미지 1장을 선택한다. 2. 선택된 이미지의 우측하단 마이봄샘 아이콘을 터치 | H25: "MEIBOGRAPHY MODE 이미지 시현화면"의 선택된 화면의 우측하단 마이봄샘 아이콘의 마이봄샘 색상이 보라색으로 시현확인
G26: 1. "REF/KER 측정 MODE 화면"으로 이동(좌측상단의 뒤로가기 아이콘 터치) 2. "REF/KER 측정 MODE 화면"으로 이동(좌측상단의 뒤로가기 아이콘 터치) 3. "REF/KER 측정 MODE 화면"으로 이동(홈 아이콘 터치) 4. "REF/KER 측정 MODE 화면"의 우측하단의 프린터 아이콘을 터치 5. HRK 동작 멈출 때까지 대기 | H26: "REF/KER 측정 MODE 화면" 좌측상단 차트번호와 OP Basic Operation 화면 좌측상단 LOAD DATA의 차트번호 비교결과, 측정화면 차트번호가 1이 더 큰지 확인 TBD - HDR( Server )에서 데이터를 수신 확인한다. (OP 어디에서 수신이미지 확인하기 위한 위치 공유요청) - Patient ID가 동일한 마이봄샘 이미지가 저장되어 있었다면, 덮어씀 (덮어쓰는 이미지 전 후 비교방법 공유요청) - 같은 환자번호에서, 여러 번 보냈을때 이미지가 덮어쓰여지는지 확인 필요. (같은 환자번호에서, 여러 번 보내는 방법 공유요청)
A27: HRK-010 | B27: Server 재연결 시 복구 | C27: 1. AP를 연결한다. 2. HDR(Server)을 연결한다. 3. 연결을 확인한 후, 임의의 Server의 AP 연결을 끊는다. 4. 임의의 Server AP 재접속을 진행한다. 5. HRK에서 끊어짐 표시를 확인한 후 데이터를 측정한다. 6. 데이터를 전송한다. 7. 전송목록에서 연결이 끊어진 Server의 아이콘 상태를 확인한다. 8. 아이콘을 눌러 재접속을 진행한 후 데이터를 전송한다. 9. Server에서 데이터를 수신 확인한다. | D27: 1. Server 접속상태 표시 2. Server와의 접속상태를 갱신하고, 데이터 전송 성공 3. 데이터 전송 실패시 에러메세지 확인( DR(Server)와 끊어짐 상태 표시 또는 전송실패 표시 ) 4. 실패 이후 재전송 성공 | E27: TC-HRK-010-WIFI-001 | F27: 테스트대상 구성 (장비 대수, S/W Version): - HRK-9000A (1대, 1.01.01A) 테스트환경 구성 : - AP(2.4GHz Band) 1대 - HDR-9000 1대 | G27: 1. AP 연결 및 인증 확인(HRK-001) 2. Server 연결 확인(HRK-002, HDR에 연결) 3. SETUP MODE 화면으로 진입(홈 화면 우측 하단 톱니바퀴 아이콘 터치) 4. SETUP MODE 화면-2 페이지-WIFI 탭으로 이동 5. TRANSFER TYPE를 Auto로 설정. 6. "REF/KER 측정 MODE 화면"으로 이동(SETUP MODE 화면에서 좌측상단 홈 아이콘 터치) | H27: "REF/KER 측정 MODE 화면" 시현확인 | I27: 전송 모드는 수동/자동 각각 설정하여 테스트 진행 측정 모드는 모드별로 테스트 진행 Server는 최소 1개, 최대 4개 늘려가면서 테스트 진행 | J27: 1. HDR / 1) 1대 / 불 2) 2대 / 2. HIIS / 3. MATE / | K27: -. HRK-9000A CCD 타입은 AP끊었을 시, 아이콘 갱신이 다소 오래걸림(Ver26) -. AP 재부팅 시, HDR에서 HRK와 자동 연결이 안되고, HRK에서 재시도를 하면 연결됨
G28: 1. 모델아이 장착 2. 조이스틱 수동조작하여 모델아이의 눈동자를 화면 위치로 대략적 배치 3. OP 홈 화면 진입(OP Basic Operation 화면에서 좌측상단 홈 아이콘 터치) 4. OP QC Settings 화면 진입(OP 홈 화면에서 Shift+MENU 터치) 5. OP QC Settings 화면의 "Commnunication 탭"의 Connection 항목을 OFF로 터치. 6. OP QC Settings 화면의 OK 터치 | H28: "REF/KER 측정 MODE 화면"에서 우측상단에서 *HDR 아이콘(미연결상태) 확인. 범례 *HDR 아이콘(미연결상태) : 회색톤 아이콘 표기, 좌상단심볼 X 파란색으로 표기
G29: 1. OP QC Settings 화면 진입(OP 홈 화면에서 Shift+MENU 터치) 2. OP QC Settings 화면의 "Commnunication 탭"의 Connection 항목을 ON로 터치. 3. OP QC Settings 화면의 OK 터치 | H29: OP 홈 화면 시현확인
G30: 1. "REF/KER 측정 MODE 화면"의 중간상단의 MEASURE 아이콘을 터치 2. "REF/KER 측정 MODE 화면"의 우측하단의 프린터 아이콘을 터치. | H30: HDR network connect 모달 시현확인
G31: 1. "REF/KER 측정 MODE 화면"의 HDR network connect 모달에서 "HDR 재연결 시도 아이콘" 터치 | H31: "REF/KER 측정 MODE 화면"의 HDR network connect 모달에서 "HDR 재연결 시도 아이콘" 이 "HDR 연결완료 아이콘" 으로 변경 확인
G32: 1. "REF/KER 측정 MODE 화면"의 HDR network connect 모달에서 OK 터치 2. OP Basic Operation 화면 진입(OP 홈 화면에서 Basic Operation 터치) 3. OP 키보드의 LOAD 버튼 터치 4. OP Basic Operation 화면 좌측상단 LOAD DATA의 RK 버튼 터치 | H32: "REF/KER 측정 MODE 화면" 좌측상단 차트번호와 OP Basic Operation 화면 좌측상단 LOAD DATA의 차트번호 비교결과, "REF/KER 측정 MODE 화면" 차트번호가 2차이 이상 임을 확인 (데이터 안들어온 것으로 판단) TBD. 정상루틴인 건지 문제인건지 확인필요
G33: 1. "REF/KER 측정 MODE 화면"의 중간상단의 MEASURE 아이콘을 터치 2. "REF/KER 측정 MODE 화면"의 우측하단의 프린터 아이콘을 터치. 3. OP Basic Operation 화면 진입(OP 홈 화면에서 Basic Operation 터치) 4. OP 키보드의 LOAD 버튼 터치 5. OP Basic Operation 화면 좌측상단 LOAD DATA의 RK 버튼 터치 | H33: "REF/KER 측정 MODE 화면" 좌측상단 차트번호와 OP Basic Operation 화면 좌측상단 LOAD DATA의 차트번호 비교결과, "REF/KER 측정 MODE 화면" 차트번호가 1이 더 큰지 확인
G34: 1. OP Basic Operation 화면 좌측상단 LOAD DATA의 차트번호 터치 | H34: "REF/KER 측정 MODE 화면"의 중간단의 좌우 R, L 데이터 목록과 OP Basic Operation 화면 상단중간 데이터 비교결과, S(SPH), C(CYLINDER), A(TBD)의 수치가 일치 상태확인(TBD. STEP 디옵터 설정 의존성 확인)
F35: 테스트대상 구성 (장비 대수, S/W Version): - HRK-9000A (1대, 1.01.01A) 테스트환경 구성 : - AP(2.4GHz Band) 1대 - HDR-9000 1대 | G35: 1. AP 연결 및 인증 확인(HRK-001) 2. Server 연결 확인(HRK-002, HDR에 연결) 3. SETUP MODE 화면으로 진입(홈 화면 우측 하단 톱니바퀴 아이콘 터치) 4. SETUP MODE 화면-2 페이지-WIFI 탭으로 이동 5. TRANSFER TYPE를 Auto로 설정. 6. "REF/KER 측정 MODE 화면"으로 이동(SETUP MODE 화면에서 좌측상단 홈 아이콘 터치) | H35: "REF/KER 측정 MODE 화면" 시현확인 | I35: 전송 모드는 수동/자동 각각 설정하여 테스트 진행 측정 모드는 모드별로 테스트 진행 Server는 최소 1개, 최대 4개 늘려가면서 테스트 진행 | J35: 1. HDR / 1) 1대 / 불 2) 2대 / 2. HIIS / 3. MATE / | K35: -. HRK-9000A CCD 타입은 AP끊었을 시, 아이콘 갱신이 다소 오래걸림(Ver26) -. AP 재부팅 시, HDR에서 HRK와 자동 연결이 안되고, HRK에서 재시도를 하면 연결됨
G36: 1. 모델아이 장착 2. 조이스틱 수동조작하여 모델아이의 눈동자를 화면 위치로 대략적 배치 3. OP 홈 화면 진입(OP Basic Operation 화면에서 좌측상단 홈 아이콘 터치) 4. OP QC Settings 화면 진입(OP 홈 화면에서 Shift+MENU 터치) 5. OP QC Settings 화면의 "Commnunication 탭"의 Connection 항목을 OFF로 터치. 6. OP QC Settings 화면의 OK 터치 | H36: "REF/KER 측정 MODE 화면"에서 우측상단에서 *HDR 아이콘(미연결상태) 확인. 범례 *HDR 아이콘(미연결상태) : 회색톤 아이콘 표기, 좌상단심볼 X 파란색으로 표기
G37: 1. OP QC Settings 화면 진입(OP 홈 화면에서 Shift+MENU 터치) 2. OP QC Settings 화면의 "Commnunication 탭"의 Connection 항목을 ON로 터치. 3. OP QC Settings 화면의 OK 터치 | H37: OP 홈 화면 시현확인
G38: 1. "REF/KER 측정 MODE 화면"의 중간상단의 MEASURE 아이콘을 터치 2. "REF/KER 측정 MODE 화면"의 우측하단의 프린터 아이콘을 터치. | H38: HDR network connect 모달 시현확인
G39: 1. "REF/KER 측정 MODE 화면"의 HDR network connect 모달에서 "HDR 재연결 시도 아이콘" 터치 | H39: "REF/KER 측정 MODE 화면"의 HDR network connect 모달에서 "HDR 재연결 시도 아이콘" 이 "HDR 연결완료 아이콘" 으로 변경 확인
G40: 1. "REF/KER 측정 MODE 화면"의 HDR network connect 모달에서 OK 터치 2. OP Basic Operation 화면 진입(OP 홈 화면에서 Basic Operation 터치) 3. OP 키보드의 LOAD 버튼 터치 4. OP Basic Operation 화면 좌측상단 LOAD DATA의 RK 버튼 터치 | H40: "REF/KER 측정 MODE 화면" 좌측상단 차트번호와 OP Basic Operation 화면 좌측상단 LOAD DATA의 차트번호 비교결과, "REF/KER 측정 MODE 화면" 차트번호가 2차이 이상 임을 확인 (데이터 안들어온 것으로 판단) TBD. 정상루틴인 건지 문제인건지 확인필요
...

Sheet Test Configs
A1: CONFIG_ID | B1: 설정명 | C1: 제조사 | D1: 제품별칭 | E1: 모델명( "_" + sub_component) | F1: S/W Version | G1: Firmware version | H1: Test Config Procedure | I1: Test Config Procedure Actual Result(재현 판단 기준) | J1: Examples to Avoid in STR | K1: TBD(To Be Determind, 협의사항) | L1: Study & Questions
A2: TC_CONFIG-HRK-001-WIFI-001-2_4GHz | C2: Huvitz | D2: 불필요 | E2: HRK-9000A | F2: TBD
C3: Huvitz | D3: 불필요 | E3: HLM-9000 | F3: TBD
C4: Huvitz | D4: 불필요 | E4: HTR-…(TBD) | F4: TBD | K4: TBD : HTR의 모델명 정보 확인방법
C5: Huvitz | D5: 불필요 | E5: HDR-9000_OP | F5: TBD
C6: Huvitz | D6: 불필요 | E6: HDR-9000_JUNCTION_BOX | F6: 1.0.5(TBD)
C7: Huvitz | D7: 불필요 | E7: HDR-9000_? | F7: TBD
C8: Huvitz | D8: 불필요 | E8: HDC-9100
C9: MERCUSYS | D9: 시험용 Router | E9: MR30G | F9: TBD
C10: MERCUSYS | D10: 시험용 Router | E10: MR30G | H10: 1. http://{router_ip} http://192.168.0.1 또는 http://192.168.1.1 공유기 하단 라벨 참고 2. SSID 설정 | I10: Smart Connect: Off or Band Steering: Off SSID 분리표기확인 2.4GHz : xxxxx 5GHz : xxxxx_5G | J10: Smart Connect: On가 아님 or Band Steering: On가 아님 | K10: TBD : 설정 및 설정완료확인방법(Wi-Fi Band에 대한 SSID 분리) 2.4GHz : xxxxx 5GHz : xxxxx_5G | L10: 2.4GHz : xxxxx (_2_4G 접미사 붙이면 명시적) 5GHz : xxxxx_5G
C11: MERCUSYS | D11: 시험용 Router | E11: MR30G | H11: Wireless / Channel | I11: 2.4GHz Channel → 1 / 6 / 11 5GHz Channel → 36 / 40 / 44 / 48 | J11: Channel: Auto가 아님 | K11: TBD : 설정 및 설정완료확인방법(Wi-Fi Channel) 2.4GHz : 1, 6 , 11 을 실무적으로 추천 5GHz : 36, 40, 44, 48 채널고정 (DFS 채널 회피) | L11: TBD 2.4GHz : 1, 6 , 11 을 실무적으로 추천 5GHz : 36, 40, 44, 48 채널고정 (DFS 채널 회피)
C12: MERCUSYS | D12: 시험용 Router | E12: MR30G | H12: Channel Width / Bandwidth | I12: 20MHz | J12: Bandwidth: Auto가 아님 | K12: TBD : 설정 및 설정완료확인방법(Channel Bandwidth) 20MHz | L12: 20MHz: 좁지만 안정적, 호환성 좋음 40MHz / 80MHz / 160MHz: 빠르지만 호환성 떨어질 TBD 20MHz 사용필요, RS9116 지원 Channel Bandwidth. RS9116 내장 Huvitz 제품군 고려필요? RS9116 내장 Huvitz 제품과 Router 호환성 고려필요?
C13: MERCUSYS | D13: 시험용 Router | E13: MR30G | H13: Wireless Mode | I13: 802.11 b/g/n mixed 또는 802.11 a/b/g/n mixed | J13: Mode: Auto가 아님 802.11ax only가 아님 WiFi 6 only가 아님 WiFi 6 mixed with WPA3가 아님 | K13: TBD : 설정 및 설정완료확인방법(Wi-Fi Wireless Mode) 802.11 a/b/g/n mixed | L13: 802.11b/g/n = Wi-Fi 4 구형 호환 좋음 802.11ac = Wi-Fi 5 802.11ax = Wi-Fi 6 802.11be = Wi-Fi 7 TBD 802.11 b/g/n mixed 또는 802.11 a/b/g/n mixed
C14: MERCUSYS | D14: 시험용 Router | E14: MR30G | H14: WPA2-Personal AES | J14: WPA3가 아님 WPA2/WPA3 mixed가 아님 TKIP가 아님 Enterprise가 아님 | K14: TBD : 설정 및 설정완료확인방법(Wifi Security) WPA2 WPA2-Personal Encryption: AES | L14: TBD WPA2 WPA2-Personal Encryption: AES
C15: Huvitz | D15: 렌즈 측정 모의용 장치 | E15: Lens TBD(x mm), | F15: - | G15: - | K15: TBD : 장비 모델명
C16: Huvitz | D16: 눈 검사 모의용 장치 | E16: 모델아이 TBD | F16: - | G16: - | K16: TBD : 장비 모델명
C17: Huvitz | D17: HDR 전원 공급용 케이블 | E17: Junction Box Power Cable | F17: - | G17: - | K17: TBD : 장비 모델명
C18: Huvitz | D18: HDC 전원 공급용 케이블 | E18: HDC Power Cable | F18: - | G18: - | K18: TBD : 장비 모델명
C19: Huvitz | D19: HLM 전원 공급용 케이블 | E19: HLM Power Cable : L-form Power Cable | F19: - | G19: - | K19: TBD : 장비 모델명
C20: Huvitz | D20: HDR 전원 및 신호 공급용 케이블 | E20: OP Signal and Power Cable | F20: - | G20: - | K20: TBD : 장비 모델명
C21: Huvitz | D21: HDR 전원 및 신호 공급용 케이블 | E21: HDR Signal and Power Cable | F21: - | G21: - | K21: TBD : 장비 모델명

Sheet Connectivity Room Routers
A1: 제조사 | B1: 제품별칭 | C1: 모델명 | D1: 일련번호 | E1: Purpose of Use | F1: Input | G1: Default SSID(5GHz) | H1: Default SSID(2.4GHz) | I1: Default Password | J1: Installed Location(Last Location) | K1: Installed Date | L1: Sticker Labeled | M1: First Connection Tested | N1: 비고
A2: ASUS | B2: Wireless Dual Band WiFi 6 Router | C2: RT-AX1800S V2 | D2: W1IG758026888HD | E2: 미국 현지 네트워크 환경 모의 | F2: 12V, 1.5A | G2: ASUS_F6 | H2: ASUS_F6 | I2: 11708421 | J2: /6th/Connectivity Room/4th_rack_black/TODO | K2: 46148 | L2: TODO | M2: TODO | N2: Quick Wi-Fi Connect QR Code
A3: NETGEAR | B3: Nighthawk AXE11000 Tri-Band WiFi 6E Router | C3: RAXE500 | D3: 6TA53B7HD00EE | E3: 미국 현지 네트워크 환경 모의 | F3: 19V, 3.16A | G3: NETGEAR11 | H3: NETGEAR11 | I3: basicbird145 | J3: /6th/Connectivity Room/4th_rack_black/TODO | K3: 46148 | L3: TODO | M3: TODO
A4: NETGEAR | B4: AC1200 WiFi Router | C4: R6120 | D4: 64E226B3A225B | E4: 미국 현지 네트워크 환경 모의 | F4: 12V, 1.5A | G4: NETGEAR56 | H4: NETGEAR56 | I4: fuzzyphoenix865 | J4: /6th/Connectivity Room/4th_rack_black/TODO | K4: 46148 | L4: TODO | M4: TODO
A5: Tenda | B5: Dual-Band Gigabit Wi-Fi 6 Router | C5: RX2 Pro | D5: ED681011551001002 V1.0 | E5: 미국 현지 네트워크 환경 모의 | F5: 12V, 1A | G5: Tenda_EFFAA0 | H5: Tenda_EFFAA0 | I5: 14796449 | J5: /6th/Connectivity Room/4th_rack_black/TODO | K5: 46148 | L5: TODO | M5: TODO
A6: TP-link | B6: AX1800 Gigabit Wi-Fi 6 Router | C6: Archer AX1800(USW) Ver:4.6 | D6: Y233061F00520 | E6: 미국 현지 네트워크 환경 모의 | F6: 12V, 1.5A | G6: TB-Link_A2B2_5G | H6: TB-Link_A2B2 | I6: 38042966 | J6: /6th/Connectivity Room/4th_rack_black/TODO | K6: 46148 | L6: TODO | M6: TODO | N6: JOIN PRESET Wi-Fi QR CODE Default Setup Link : http://tplinkwifi.net
A7: TP-link | B7: AX1500 Wi-Fi 6 Router | C7: Archer AX10 | D7: Y258005000560 | E7: 미국 현지 네트워크 환경 모의 | F7: 12V, 1A | G7: TB-Link_35E8_5G | H7: TB-Link_35E8 | I7: 24795388 | J7: /6th/Connectivity Room/4th_rack_black/TODO | K7: 46148 | L7: TODO | M7: TODO
A8: MERCUSYS | B8: TODO | C8: MR30G | D8: 2232318003141

Sheet Test Configs (2)
A1: Test Config ID | B1: 시험환경별칭 | C1: 시험대상 | D1: 시험환경 | E1: 시험조건 | F1: TBD(To Be Determined, 협의사항) | G1: 결정사항
A5: Firmware version | B5: Test Config Procedure | C5: Test Config Procedure Actual Result(재현 판단 기준) | D5: Examples to Avoid in STR | E5: TBD(To Be Determind, 협의사항) | F5: Study & Questions
E8: TBD : HTR의 모델명 정보 확인방법
B13: Router Test Case Procedure
A14: AP 설정 및 구성 | B14: 1. http://{router_ip} http://192.168.0.1 또는 http://192.168.1.1 공유기 하단 라벨 참고 2. SSID 설정 | C14: Smart Connect: Off or Band Steering: Off SSID 분리표기확인 2.4GHz : xxxxx 5GHz : xxxxx_5G | D14: Smart Connect: On가 아님 or Band Steering: On가 아님 | E14: TBD : 설정 및 설정완료확인방법(Wi-Fi Band에 대한 SSID 분리) 2.4GHz : xxxxx 5GHz : xxxxx_5G | F14: 2.4GHz : xxxxx (_2_4G 접미사 붙이면 명시적) 5GHz : xxxxx_5G | J14: 시험환경구성절차_재현판단기준
B15: 1. TBD(Wireless / Channel) | C15: 2.4GHz Channel → 1 / 6 / 11 5GHz Channel → 36 / 40 / 44 / 48 | D15: Channel: Auto가 아님 | E15: TBD : 설정 및 설정완료확인방법(Wi-Fi Channel) 2.4GHz : 1, 6 , 11 을 실무적으로 추천 5GHz : 36, 40, 44, 48 채널고정 (DFS 채널 회피) | F15: TBD 2.4GHz : 1, 6 , 11 을 실무적으로 추천 5GHz : 36, 40, 44, 48 채널고정 (DFS 채널 회피)
B16: 1. TBD(Channel Width / Bandwidth) | C16: 20MHz | D16: Bandwidth: Auto가 아님 | E16: TBD : 설정 및 설정완료확인방법(Channel Bandwidth) 20MHz | F16: 20MHz: 좁지만 안정적, 호환성 좋음 40MHz / 80MHz / 160MHz: 빠르지만 호환성 떨어질 TBD 20MHz 사용필요, RS9116 지원 Channel Bandwidth. RS9116 내장 Huvitz 제품군 고려필요? RS9116 내장 Huvitz 제품과 Router 호환성 고려필요?
B17: 1. TBD(Wireless Mode) | C17: 802.11 b/g/n mixed 또는 802.11 a/b/g/n mixed | D17: Mode: Auto가 아님 802.11ax only가 아님 WiFi 6 only가 아님 WiFi 6 mixed with WPA3가 아님 | E17: TBD : 설정 및 설정완료확인방법(Wi-Fi Wireless Mode) 802.11 a/b/g/n mixed | F17: 802.11b/g/n = Wi-Fi 4 구형 호환 좋음 802.11ac = Wi-Fi 5 802.11ax = Wi-Fi 6 802.11be = Wi-Fi 7 TBD 802.11 b/g/n mixed 또는 802.11 a/b/g/n mixed
B18: 1. TBD(WPA2-보안) 2. Personal 3. AES | D18: WPA3가 아님 WPA2/WPA3 mixed가 아님 TKIP가 아님 Enterprise가 아님 | E18: TBD : 설정 및 설정완료확인방법(Wifi Security) WPA2 WPA2-Personal Encryption: AES | F18: TBD WPA2 WPA2-Personal Encryption: AES
A19: - | E19: TBD : 장비 모델명
A20: - | E20: TBD : 장비 모델명
A21: - | E21: TBD : 장비 모델명
A22: - | E22: TBD : 장비 모델명
A23: - | E23: TBD : 장비 모델명
A24: - | E24: TBD : 장비 모델명
A25: - | E25: TBD : 장비 모델명

Sheet Test Cases (2)
A1: Test Senario ID | B1: 테스트 항목 | C1: 테스트 절차 | D1: 기대 결과 | E1: Test Case ID | F1: Test Config ID | G1: Test Procedure | H1: Test Procedure Actual Result(재현 판단 기준) | I1: 비고 | J1: 결과 판정 | K1: 특이사항
A2: HRK-001 | B2: AP 연결 및 인증 확인 | C2: 1. 사용자 설정에서 WIFI - BAND를 2.4GHz / 5GHz 선택한다. 2. AP SSID 스캔을 위해 SCAN버튼을 touch한다. 3. AP List 모달(팝업)에서 사용할 AP를 터치. 4. AP 의 ID/Password 를 입력하고, Verify 버튼을 touch한다. 5. 인증 확인 메시지를 확인한다. - 성공시: AP Password is okay! - 실패시: Error code 확인 | D2: 1. 연결 가능한 AP 목록 (SSID/RSSI 순서) 2. AP 연결 성공 3. AP 인증 성공 | E2: TC-HRK-001-WIFI-001 | F2: 테스트대상 구성 (장비 대수, S/W Version): - HRK-9000A (1대, 1.01.01A) 테스트환경 구성 : - AP(2.4GHz Band) 1대 | G2: 1. SETUP MODE 화면으로 진입(홈 화면 우측 하단 톱니바퀴 아이콘 터치) 2. SETUP MODE 화면-2 페이지-WIFI 탭 으로이동 3. BAND 항목을 2.4GHz로 터치 4. SCAN 버튼 터치. | H2: AP List에 SETUP 화면에 RSSI 신호강도가 강한 순에서 작은 순으로 SSID가 배치확인 | I2: 2.4GHz, 5GHz AP 에서 각각 수행 연결 실패시, 에러메세지 확인 최초 연결 후 AP 끊어지는 경우 체크 필요 | J2: 1. HDR / 1) 1대 / 2) 2대 / 2. HIIS / 3. MATE / | K2: SETUP MODE 화면 진입 위해 "홈 화면 우측 하단 톱니바퀴 아이콘 터치" 시 간헐적 미인식
G3: 1. AP List 모달(팝업)에서 사용할 AP를 터치. | H3: SETUP MODE 화면-2 페이지-WIFI 탭 의 AP SSID 항목에 선택한 SSID 가 시현
G4: 1. AP Password 입력 2. Verify 버튼 터치 3. AP Password is okay! 모달 시현 대기 4. AP Password is okay! 모달 OK 버튼 터치 | H4: 최초 연결 후 TBD 초 간 AP 끊어짐 없고, 연결관련 에러메세지 없이, 측정화면의 우측상단 Wi-Fi & HDR 정상연결 상태확인(아래의 범례와 같은 상태) 범례 *Wi-Fi 아이콘(정상 연결상태): 파란색으로 RSSI 신호세기 표기, 우하단심볼 미표기
A5: HRK-002 | B5: Server 연결 확인 | C5: 1. AP를 연결한다. 2. 사용자 설정에서 HDR IP / Port 를 입력한다. (port (default: 42000)) 3. 사용자 설정을 나와서 HDR(Server) 연결을 확인한다. 4. 오른쪽 위 상단의 ICON 확인 - 제품 4대 연결 가능. (HDR / HRK-Mate / HIIS) - 연결 성공 O, 연결 실패 X로 icon 위에 표시 (모두 연결시 O/X 표시 안함.) | D5: 1. DR 연결 성공 | E5: TC-HRK-002-WIFI-001 | F5: 테스트대상 구성 (장비 대수, S/W Version): - HRK-9000A (1대, 1.01.01A) 테스트환경 구성 : - AP(2.4GHz Band) 1대 - HDR-9000 1대 | G5: 1. AP 연결 및 인증 확인(HRK-001) 2. SETUP MODE 화면으로 진입(홈 화면 우측 하단 톱니바퀴 아이콘 터치) 3. SETUP MODE 화면-2 페이지-HDR IP 1탭으로 이동 4. HDR Nickname 입력 ex> HDR9000_1(연결할 Nickname) 5. HDR IP 입력 ex> 192.168.***.***(연결할 HDR IP) 6. HDR Port 입력 ex> 42000(연결할 Port) 7. HDR 연결할 항목에 대한 Checkbox를 터치(V 표기 시현되도록) | H5: 홈 화면의 우측상단 Wi-Fi & HDR 정상연결 상태확인(아래의 범례와 같은 상태) 범례 *Wi-Fi 아이콘 : 회색으로 RSSI 신호세기 표기상태, 좌상단심볼 미표기 *DR 아이콘 : 회색으로 DR 표기, 좌상단심볼 미표기 | I5: 최소 1개, 최대4개 늘려가면서 연결 시도 이후 모든 전송 테스트도 Server 개수 늘려가면서 진행 | J5: 1. HDR / 1) 1대 / 합 2) 2대 / 2. HIIS / 3. MATE /
A6: HRK-003 | B6: 측정데이터 전송(수동모드) | C6: 1. AP를 연결한다. 2. HDR(Server)을 연결한다. 3. 사용자 설정에서 TRANSFER TYPE(전송모드)를 수동(Manual)으로 설정한다. 4. REF / KER 측정 모드에서 데이터를 측정한다. 5. 프린트 버튼을 누르거나, 화면에 프린트 버튼을 touch 한다. 6. HDR network connect 팝업창에서 HDR (server) 버튼을 touch하여, 데이터를 전송한다. 7. HDR( Server )에서 데이터를 수신 확인한다. 8. 전송 이후, AP 또는 Server 연결이 끊어지는지 확인한다. | D6: 1. 데이터 전송 성공 2. 데이터 전송 실패시 에러메세지 확인( DR(Server)와 끊어짐 상태 표시 또는 전송실패 표시 ) 3. 실패 이후 재전송 성공 | E6: TC-HRK-003-WIFI-001 | F6: 테스트대상 구성 (장비 대수, S/W Version): - HRK-9000A (1대, 1.01.01A) 테스트환경 구성 : - AP(2.4GHz Band) 1대 - HDR-9000 1대 | G6: 1. AP 연결 및 인증 확인(HRK-001) 2. Server 연결 확인(HRK-002, HDR에 연결) 3. SETUP MODE 화면으로 진입(홈 화면 우측 하단 톱니바퀴 아이콘 터치) 4. SETUP MODE 화면-2 페이지-WIFI 탭으로 이동 5. TRANSFER TYPE를 Manual으로 설정. 6. "REF/KER 측정 MODE 화면"으로 이동(SETUP MODE 화면에서 좌측상단 홈 아이콘 터치) 7. 모델아이 장착 8. 조이스틱 수동조작하여 모델아이의 눈동자를 화면 위치로 대략적 배치 9. "REF/KER 측정 MODE 화면"의 중간상단의 MEASURE 아이콘을 터치 | H6: HRK가 "REF/KER 측정 MODE 화면"에서 모델아이 측정한 상태로 멈춤 확인 | I6: 측정 모드는 모드별로 테스트 진행 | J6: 1. HDR / 1) 1대 / 합 2) 2대 / 2. HIIS / 3. MATE /
G7: 1. "REF/KER 측정 MODE 화면"의 우측하단의 프린터 아이콘을 터치. 2. HDR network connect 팝업창에서 HDR (server) 아이콘을 터치. | H7: "REF/KER 측정 MODE 화면"의 HDR network connect 팝업창에서 HDR (server) 아이콘이 문서교환 아이콘으로 변경시현확인
G8: 1. HDR network connect 팝업창에서 OK 버튼 터치 | H8: HRK가 움직이며 ALIGN CENTER 비모달 시현 후 동공의 CENTER에서 멈춤
G9: 1. OP 키보드의 LOAD 버튼 클릭 2. OP Basic Operation 화면 좌측상단 LOAD DATA의 RK 버튼 터치 | H9: "REF/KER 측정 MODE 화면" 좌측상단 차트번호와 OP Basic Operation 화면 좌측상단 LOAD DATA의 차트번호 비교결과, 측정화면 차트번호가 1이 더 큰지 확인
G10: 1. OP Basic Operation 화면 좌측상단 LOAD DATA의 차트번호 터치 | H10: "REF/KER 측정 MODE 화면"의 중간단의 좌우 R, L 데이터 목록과 OP Basic Operation 화면 상단중간 데이터 비교결과, S(SPH), C(CYLINDER), A(TBD)의 수치가 일치 상태확인(TBD. STEP 디옵터 설정 의존성 확인)
A11: HRK-004 | B11: 측정데이터 전송(자동모드) | C11: 1. AP를 연결한다. 2. HDR(Server)을 연결한다. 3. 사용자 설정에서 TRANSFER TYPE(전송모드)를 자동(Auto)으로 설정한다. 4. REF / KER 측정 모드에서 데이터를 측정한다. 5. 프린트 버튼을 누르거나, 화면에 프린트 버튼을 touch 한다. 6. HDR (Server) 가 모두 연결된 경우, 팝업창이 뜨지 않고 데이터가 전송되는지 확인한다. - 1대 이상 연결된 경우, 모두 연결된 상태확인 - 여러대 중 1~2대 연결이 끊어진 상태확인 (전송모드가 자동이어도, HDR network connect 팝업창이 떠야 정상) 7. HDR( Server )에서 데이터를 수신 확인한다. 8. 전송 이후, AP 또는 Server 연결이 끊어지는지 확인한다. | D11: 1. 데이터 전송 성공 2. 데이터 전송 실패시 에러메세지 확인( DR(Server)와 끊어짐 상태 표시 또는 전송실패 표시 ) 3. 실패 이후 재전송 성공 | E11: TC-HRK-004-WIFI-001 | F11: 테스트대상 구성 (장비 대수, S/W Version): - HRK-9000A (1대, 1.01.01A) 테스트환경 구성 : - AP(2.4GHz Band) 1대 - HDR-9000 1대 | G11: 1. AP 연결 및 인증 확인(HRK-001) 2. Server 연결 확인(HRK-002, HDR에 연결) 3. SETUP MODE 화면으로 진입(홈 화면 우측 하단 톱니바퀴 아이콘 터치) 4. SETUP MODE 화면-2 페이지-WIFI 탭으로 이동 5. TRANSFER TYPE를 Auto로 설정. 6. "REF/KER 측정 MODE 화면"으로 이동(SETUP MODE 화면에서 좌측상단 홈 아이콘 터치) 7. 모델아이 장착 8. 조이스틱 수동조작하여 모델아이의 눈동자를 화면 위치로 대략적 배치 9. "REF/KER 측정 MODE 화면"의 중간상단의 MEASURE 아이콘을 터치 | H11: HRK가 "REF/KER 측정 MODE 화면"에서 모델아이 측정한 상태로 멈춤 확인 | I11: 측정 모드는 모드별로 테스트 진행 | J11: 1. HDR / 1) 1대 / 합 2) 2대 / 2. HIIS / 3. MATE /
G12: 1. "REF/KER 측정 MODE 화면"의 우측하단의 프린터 아이콘을 터치. | H12: "REF/KER 측정 MODE 화면"의 HDR network connect 팝업창이 뜨지 않고, HRK가 움직이며 ALIGN CENTER 비모달 시현 후 동공의 CENTER에서 멈춤
G13: 1. OP 키보드의 LOAD 버튼 클릭 2. OP Basic Operation 화면 좌측상단 LOAD DATA의 RK 버튼 터치 | H13: "REF/KER 측정 MODE 화면" 좌측상단 차트번호와 OP Basic Operation 화면 좌측상단 LOAD DATA의 차트번호 비교결과, 측정화면 차트번호가 1이 더 큰지 확인 TBD - 1대 이상 연결된 경우, 모두 연결된 상태확인 - 여러대 중 1~2대 연결이 끊어진 상태확인 (전송모드가 자동이어도, HDR network connect 팝업창이 떠야 정상)
G14: 1. OP Basic Operation 화면 좌측상단 LOAD DATA의 차트번호 터치 | H14: "REF/KER 측정 MODE 화면"의 중간단의 좌우 R, L 데이터 목록과 OP Basic Operation 화면 상단중간 데이터 비교결과, S(SPH), C(CYLINDER), A(TBD)의 수치가 일치 상태확인(TBD. STEP 디옵터 설정 의존성 확인)
A15: HRK-005 | B15: 이미지(IOL) 촬영 후 전송 | C15: 1. RETRO-ILLUMINATION MODE에 들어간다. 2. 이미지를 촬영한다. - 조이스틱 누르거나, 화면에 CAPTURE touch - 최소1장 ~ 최대4장 capture, OD/OS 무관 3. 프린트 버튼을 눌러 데이터를 전송한다. - Image Transmitting (1/4) : 캡쳐한 이미지 4장중 1장 전송중 - Image Transfer Successful! : 이미지 전송 성공 - Image Transfer Failed! : 이미지 전송 실패 4. 전송이 완료 되면, HDR( Server )에서 데이터를 수신 확인한다. 5. 전송 이후, AP 또는 Server 연결이 끊어지는지 확인한다. | D15: 1. 데이터 전송 성공 2. 데이터 전송 실패시 에러메세지 확인( DR(Server)와 끊어짐 상태 표시 또는 전송실패 표시 ) 3. 실패 이후 재전송 성공 4. HDR이 Server 목록에 있더라도 전송 성공 하는지 유무 | E15: TC-HRK-005-WIFI-001 | F15: 테스트대상 구성 (장비 대수, S/W Version): - HRK-9000A (1대, 1.01.01A) 테스트환경 구성 : - AP(2.4GHz Band) 1대 - HDR-9000 1대 | G15: 1. "REF/KER 측정 MODE 화면"의 좌측하단 부기기능 아이콘(2x2 Matrix 아이콘, 우상단, 좌하단 2개 파란색, 나머지 2개 회색) 터치 2. Retro-ILL 터치 3. HRK 동작 멈출 때까지 대기 4. 조이스틱의 Shot 버튼 누름 | H15: RETRO-ILLUMINATION MODE 화면 하단중간 Image Captured 시현확인 | I15: 같은 환자번호에서, 여러 번 보냈을때 이미지가 덮어쓰여지는지 확인 필요. | J15: 1. HDR / 전송 기능 없음 1) 1대 / 2) 2대 / 2. HIIS / 3. MATE /
G16: 1. "REF/KER 측정 MODE 화면"으로 이동(좌측상단의 홈 아이콘 터치) 2. "REF/KER 측정 MODE 화면"의 우측하단의 프린터 아이콘을 터치. | H16: "REF/KER 측정 MODE 화면" 좌측상단 차트번호와 OP Basic Operation 화면 좌측상단 LOAD DATA의 차트번호 비교결과, 측정화면 차트번호가 1이 더 큰지 확인 TBD - HDR( Server )에서 데이터를 수신 확인한다. (OP 어디에서 수신이미지 확인하기 위한 위치 공유요청) TBD - Patient ID가 동일한 마이봄샘 이미지가 저장되어 있었다면, 덮어씀 (덮어쓰는 이미지 전 후 비교방법 공유요청) TBD - 같은 환자번호에서, 여러 번 보냈을때 이미지가 덮어쓰여지는지 확인 필요. (같은 환자번호에서, 여러 번 보내는 방법 공유요청)
A17: HRK-006 | B17: 이미지( COLOR ) 촬영 후 전송 | C17: 1. COLOR VIEW MODE에 들어간다. 2. 이미지를 촬영한다. - 조이스틱 누르거나, 화면에 CAPTURE touch - 최소1장 ~ 최대4장 capture, OD/OS 무관 3. 프린트 버튼을 눌러 데이터를 전송한다. - Image Transmitting (1/4) : 캡쳐한 이미지 4장중 1장 전송중 - Image Transfer Successful! : 이미지 전송 성공 - Image Transfer Failed! : 이미지 전송 실패 4. 전송이 완료 되면, HDR( Server )에서 데이터를 수신 확인한다. 5. 전송 이후, AP 또는 Server 연결이 끊어지는지 확인한다. | D17: 1. 데이터 전송 성공 2. 데이터 전송 실패시 에러메세지 확인( DR(Server)와 끊어짐 상태 표시 또는 전송실패 표시 ) 3. 실패 이후 재전송 성공 4. HDR이 Server 목록에 있더라도 전송 성공 하는지 유무 | E17: TC-HRK-006-WIFI-001 | F17: 테스트대상 구성 (장비 대수, S/W Version): - HRK-9000A (1대, 1.01.01A) 테스트환경 구성 : - AP(2.4GHz Band) 1대 - HDR-9000 1대 | G17: 1. "REF/KER 측정 MODE 화면"의 좌측하단 부기기능 아이콘(2x2 Matrix 아이콘, 우상단, 좌하단 2개 파란색, 나머지 2개 회색) 터치 2. COLOR 터치 3. HRK 동작 멈출 때까지 대기 4. 조이스틱의 Shot 버튼 누름 | H17: COLOR VIEW MODE 화면 하단중간 Image Captured 시현확인 | I17: 같은 환자번호에서, 여러 번 보냈을때 이미지가 덮어쓰여지는지 확인 필요. | J17: 1. HDR / 전송 기능 없음 1) 1대 / 2) 2대 / 2. HIIS / 3. MATE /
G18: 1. "REF/KER 측정 MODE 화면"으로 이동(좌측상단의 홈 아이콘 터치) 2. "REF/KER 측정 MODE 화면"의 우측하단의 프린터 아이콘을 터치. 3. HRK 동작 멈출 때까지 대기 | H18: "REF/KER 측정 MODE 화면" 좌측상단 차트번호와 OP Basic Operation 화면 좌측상단 LOAD DATA의 차트번호 비교결과, 측정화면 차트번호가 1이 더 큰지 확인 TBD - HDR( Server )에서 데이터를 수신 확인한다. (OP 어디에서 수신이미지 확인하기 위한 위치 공유요청) TBD - Patient ID가 동일한 마이봄샘 이미지가 저장되어 있었다면, 덮어씀 (덮어쓰는 이미지 전 후 비교방법 공유요청) TBD - 같은 환자번호에서, 여러 번 보냈을때 이미지가 덮어쓰여지는지 확인 필요. (같은 환자번호에서, 여러 번 보내는 방법 공유요청)
A19: HRK-007 | B19: 이미지( TFBUT ) 촬영 후 전송 | C19: 1. TFBUT MODE에 들어간다. 2. 이미지를 촬영한다. - 조이스틱 누르거나, 화면에 CAPTURE touch - 최소1장 ~ 최대4장 capture, OD/OS 무관 3. 프린트 버튼을 눌러 데이터를 전송한다. - Image Transmitting (1/4) : 캡쳐한 이미지 4장중 1장 전송중 - Image Transfer Successful! : 이미지 전송 성공 - Image Transfer Failed! : 이미지 전송 실패 4. 전송이 완료 되면, HDR( Server )에서 데이터를 수신 확인한다. 5. 전송 이후, AP 또는 Server 연결이 끊어지는지 확인한다. | D19: 1. 데이터 전송 성공 2. 데이터 전송 실패시 에러메세지 확인( DR(Server)와 끊어짐 상태 표시 또는 전송실패 표시 ) 3. 실패 이후 재전송 성공 4. HDR이 Server 목록에 있더라도 전송 성공 하는지 유무 | E19: TC-HRK-007-WIFI-001 | F19: 테스트대상 구성 (장비 대수, S/W Version): - HRK-9000A (1대, 1.01.01A) 테스트환경 구성 : - AP(2.4GHz Band) 1대 - HDR-9000 1대 | G19: 1. "REF/KER 측정 MODE 화면"의 좌측하단 부기기능 아이콘(2x2 Matrix 아이콘, 우상단, 좌하단 2개 파란색, 나머지 2개 회색) 터치 2. TFBUT 터치 3. HRK 동작 멈출 때까지 대기 4. 조이스틱의 Shot 버튼 누름 | H19: TFBUT MODE 화면 하단중간 Image Captured 시현확인 | I19: 같은 환자번호에서, 여러 번 보냈을때 이미지가 덮어쓰여지는지 확인 필요. Server 가 HIIS-1인 경우, duration time 출력 여부 확인 필요. | J19: 1. HDR / 전송 기능 없음 1) 1대 / 2) 2대 / 2. HIIS / 3. MATE /
G20: 1. "REF/KER 측정 MODE 화면"으로 이동(좌측상단의 홈 아이콘 터치) 2. "REF/KER 측정 MODE 화면"의 우측하단의 프린터 아이콘을 터치. 3. HRK 동작 멈출 때까지 대기 | H20: "REF/KER 측정 MODE 화면" 좌측상단 차트번호와 OP Basic Operation 화면 좌측상단 LOAD DATA의 차트번호 비교결과, 측정화면 차트번호가 1이 더 큰지 확인 TBD - HDR( Server )에서 데이터를 수신 확인한다. (OP 어디에서 수신이미지 확인하기 위한 위치 공유요청) TBD - Patient ID가 동일한 마이봄샘 이미지가 저장되어 있었다면, 덮어씀 (덮어쓰는 이미지 전 후 비교방법 공유요청) TBD - 같은 환자번호에서, 여러 번 보냈을때 이미지가 덮어쓰여지는지 확인 필요. (같은 환자번호에서, 여러 번 보내는 방법 공유요청)
A21: HRK-008 | B21: 이미지( MEIBO ) 촬영 후 전송 | C21: 1. MEIBOGRAPHY MODE에 들어간다. 2. 이미지를 촬영한다. - 조이스틱 누르거나, 화면에 CAPTURE touch - 최소1장 ~ 최대4장 capture, OD/OS 무관 3. 프린트 버튼을 눌러 데이터를 전송한다. - Image Transmitting (1/4) : 캡쳐한 이미지 4장중 1장 전송중 - Image Transfer Successful! : 이미지 전송 성공 - Image Transfer Failed! : 이미지 전송 실패 4. 전송이 완료 되면, HDR( Server )에서 데이터를 수신 확인한다. 5. 전송 이후, AP 또는 Server 연결이 끊어지는지 확인한다. | D21: 1. 데이터 전송 성공 2. 데이터 전송 실패시 에러메세지 확인( DR(Server)와 끊어짐 상태 표시 또는 전송실패 표시 ) 3. 실패 이후 재전송 성공 4. HDR이 Server 목록에 있더라도 전송 성공 하는지 유무 | E21: TC-HRK-008-WIFI-001 | F21: 테스트대상 구성 (장비 대수, S/W Version): - HRK-9000A (1대, 1.01.01A) 테스트환경 구성 : - AP(2.4GHz Band) 1대 - HDR-9000 1대 | G21: 1. "REF/KER 측정 MODE 화면"의 좌측하단 부기기능 아이콘(2x2 Matrix 아이콘, 우상단, 좌하단 2개 파란색, 나머지 2개 회색) 터치 2. MEIBO 터치 3. HRK 동작 멈출 때까지 대기 4. 조이스틱의 Shot 버튼 누름 | H21: MEIBOGRAPHY MODE 화면의 하단중간 Image Captured 시현확인 | I21: 같은 환자번호에서, 여러 번 보냈을때 이미지가 덮어쓰여지는지 확인 필요. | J21: 1. HDR / 전송 기능 없음 1) 1대 / 2) 2대 / 2. HIIS / 3. MATE /
G22: 1. "REF/KER 측정 MODE 화면"으로 이동(좌측상단의 홈 아이콘 터치) 2. "REF/KER 측정 MODE 화면"의 우측하단의 프린터 아이콘을 터치 3. HRK 동작 멈출 때까지 대기 | H22: "REF/KER 측정 MODE 화면" 좌측상단 차트번호와 OP Basic Operation 화면 좌측상단 LOAD DATA의 차트번호 비교결과, 측정화면 차트번호가 1이 더 큰지 확인 TBD - HDR( Server )에서 데이터를 수신 확인한다. (OP 어디에서 수신이미지 확인하기 위한 위치 공유요청) TBD - Patient ID가 동일한 마이봄샘 이미지가 저장되어 있었다면, 덮어씀 (덮어쓰는 이미지 전 후 비교방법 공유요청) TBD - 같은 환자번호에서, 여러 번 보냈을때 이미지가 덮어쓰여지는지 확인 필요. (같은 환자번호에서, 여러 번 보내는 방법 공유요청)
A23: HRK-009 | B23: 이미지( MEIBO - 강조 ) 전송 | C23: 1. MEIBOGRAPHY MODE에 들어간다. 2. 이미지를 촬영한다. 3. 눈 모양 버튼을 touch하여 이미지 display 화면으로 들어가서 마이봄샘을 강조할 이미지 1장을 선택한다. 4. 아이콘 버튼을 touch하여 마이봄샘을 강조한다. 5. 프린트 버튼을 눌러 데이터를 전송한다. - Image Transmitting (1/1) : 캡쳐한 이미지 1장 전송중 - Image Transfer Successful! : 이미지 전송 성공 - Image Transfer Failed! : 이미지 전송 실패 6. 전송이 완료 되면, HDR( Server )에서 데이터를 수신 확인한다. (Patient ID가 동일한 마이봄샘 이미지가 저장되어 있었다면, 덮어씀) 7. 전송 이후, AP 또는 Server 연결이 끊어지는지 확인한다. | D23: 1. 데이터 전송 성공 2. 데이터 전송 실패시 에러메세지 확인( DR(Server)와 끊어짐 상태 표시 또는 전송실패 표시 ) 3. 실패 이후 재전송 성공 4. HDR이 Server 목록에 있더라도 전송 성공 하는지 유무 | E23: TC-HRK-009-WIFI-001 | F23: 테스트대상 구성 (장비 대수, S/W Version): - HRK-9000A (1대, 1.01.01A) 테스트환경 구성 : - AP(2.4GHz Band) 1대 - HDR-9000 1대 | G23: 1. "REF/KER 측정 MODE 화면"의 좌측하단 부기기능 아이콘(2x2 Matrix 아이콘, 우상단, 좌하단 2개 파란색, 나머지 2개 회색) 터치 2. MEIBO 터치 3. HRK 동작 멈출 때까지 대기 4. 조이스틱의 Shot 아이콘 누름 | H23: MEIBOGRAPHY MODE 화면의 하단중간 Image Captured 시현확인 | I23: 같은 환자번호에서, 여러 번 보냈을때 이미지가 덮어쓰여지는지 확인 필요. | J23: 1. HDR / 전송 기능 없음 1) 1대 / 2) 2대 / 2. HIIS / 3. MATE /
G24: 1. MEIBOGRAPHY 화면의 우측하단 이중 사각형 안 눈모양 아이콘을 터치 | H24: "MEIBOGRAPHY MODE 이미지 시현화면"으로 화면전환 확인 (4개의 이미지가 한 화면에 4분할 되어 시현)
G25: 1. MEIBOGRAPHY MODE 이미지 시현화면의 4장 중 마이봄샘을 강조할 이미지 1장을 선택한다. 2. 선택된 이미지의 우측하단 마이봄샘 아이콘을 터치 | H25: "MEIBOGRAPHY MODE 이미지 시현화면"의 선택된 화면의 우측하단 마이봄샘 아이콘의 마이봄샘 색상이 보라색으로 시현확인
G26: 1. "REF/KER 측정 MODE 화면"으로 이동(좌측상단의 뒤로가기 아이콘 터치) 2. "REF/KER 측정 MODE 화면"으로 이동(좌측상단의 뒤로가기 아이콘 터치) 3. "REF/KER 측정 MODE 화면"으로 이동(홈 아이콘 터치) 4. "REF/KER 측정 MODE 화면"의 우측하단의 프린터 아이콘을 터치 5. HRK 동작 멈출 때까지 대기 | H26: "REF/KER 측정 MODE 화면" 좌측상단 차트번호와 OP Basic Operation 화면 좌측상단 LOAD DATA의 차트번호 비교결과, 측정화면 차트번호가 1이 더 큰지 확인 TBD - HDR( Server )에서 데이터를 수신 확인한다. (OP 어디에서 수신이미지 확인하기 위한 위치 공유요청) - Patient ID가 동일한 마이봄샘 이미지가 저장되어 있었다면, 덮어씀 (덮어쓰는 이미지 전 후 비교방법 공유요청) - 같은 환자번호에서, 여러 번 보냈을때 이미지가 덮어쓰여지는지 확인 필요. (같은 환자번호에서, 여러 번 보내는 방법 공유요청)
A27: HRK-010 | B27: Server 재연결 시 복구 | C27: 1. AP를 연결한다. 2. HDR(Server)을 연결한다. 3. 연결을 확인한 후, 임의의 Server의 AP 연결을 끊는다. 4. 임의의 Server AP 재접속을 진행한다. 5. HRK에서 끊어짐 표시를 확인한 후 데이터를 측정한다. 6. 데이터를 전송한다. 7. 전송목록에서 연결이 끊어진 Server의 아이콘 상태를 확인한다. 8. 아이콘을 눌러 재접속을 진행한 후 데이터를 전송한다. 9. Server에서 데이터를 수신 확인한다. | D27: 1. Server 접속상태 표시 2. Server와의 접속상태를 갱신하고, 데이터 전송 성공 3. 데이터 전송 실패시 에러메세지 확인( DR(Server)와 끊어짐 상태 표시 또는 전송실패 표시 ) 4. 실패 이후 재전송 성공 | E27: TC-HRK-010-WIFI-001 | F27: 테스트대상 구성 (장비 대수, S/W Version): - HRK-9000A (1대, 1.01.01A) 테스트환경 구성 : - AP(2.4GHz Band) 1대 - HDR-9000 1대 | G27: 1. AP 연결 및 인증 확인(HRK-001) 2. Server 연결 확인(HRK-002, HDR에 연결) 3. SETUP MODE 화면으로 진입(홈 화면 우측 하단 톱니바퀴 아이콘 터치) 4. SETUP MODE 화면-2 페이지-WIFI 탭으로 이동 5. TRANSFER TYPE를 Auto로 설정. 6. "REF/KER 측정 MODE 화면"으로 이동(SETUP MODE 화면에서 좌측상단 홈 아이콘 터치) | H27: "REF/KER 측정 MODE 화면" 시현확인 | I27: 전송 모드는 수동/자동 각각 설정하여 테스트 진행 측정 모드는 모드별로 테스트 진행 Server는 최소 1개, 최대 4개 늘려가면서 테스트 진행 | J27: 1. HDR / 1) 1대 / 불 2) 2대 / 2. HIIS / 3. MATE / | K27: -. HRK-9000A CCD 타입은 AP끊었을 시, 아이콘 갱신이 다소 오래걸림(Ver26) -. AP 재부팅 시, HDR에서 HRK와 자동 연결이 안되고, HRK에서 재시도를 하면 연결됨
G28: 1. 모델아이 장착 2. 조이스틱 수동조작하여 모델아이의 눈동자를 화면 위치로 대략적 배치 3. OP 홈 화면 진입(OP Basic Operation 화면에서 좌측상단 홈 아이콘 터치) 4. OP QC Settings 화면 진입(OP 홈 화면에서 Shift+MENU 터치) 5. OP QC Settings 화면의 "Commnunication 탭"의 Connection 항목을 OFF로 터치. 6. OP QC Settings 화면의 OK 터치 | H28: "REF/KER 측정 MODE 화면"에서 우측상단에서 *HDR 아이콘(미연결상태) 확인. 범례 *HDR 아이콘(미연결상태) : 회색톤 아이콘 표기, 좌상단심볼 X 파란색으로 표기
G29: 1. OP QC Settings 화면 진입(OP 홈 화면에서 Shift+MENU 터치) 2. OP QC Settings 화면의 "Commnunication 탭"의 Connection 항목을 ON로 터치. 3. OP QC Settings 화면의 OK 터치 | H29: OP 홈 화면 시현확인
G30: 1. "REF/KER 측정 MODE 화면"의 중간상단의 MEASURE 아이콘을 터치 2. "REF/KER 측정 MODE 화면"의 우측하단의 프린터 아이콘을 터치. | H30: HDR network connect 모달 시현확인
G31: 1. "REF/KER 측정 MODE 화면"의 HDR network connect 모달에서 "HDR 재연결 시도 아이콘" 터치 | H31: "REF/KER 측정 MODE 화면"의 HDR network connect 모달에서 "HDR 재연결 시도 아이콘" 이 "HDR 연결완료 아이콘" 으로 변경 확인
G32: 1. "REF/KER 측정 MODE 화면"의 HDR network connect 모달에서 OK 터치 2. OP Basic Operation 화면 진입(OP 홈 화면에서 Basic Operation 터치) 3. OP 키보드의 LOAD 버튼 터치 4. OP Basic Operation 화면 좌측상단 LOAD DATA의 RK 버튼 터치 | H32: "REF/KER 측정 MODE 화면" 좌측상단 차트번호와 OP Basic Operation 화면 좌측상단 LOAD DATA의 차트번호 비교결과, "REF/KER 측정 MODE 화면" 차트번호가 2차이 이상 임을 확인 (데이터 안들어온 것으로 판단) TBD. 정상루틴인 건지 문제인건지 확인필요
G33: 1. "REF/KER 측정 MODE 화면"의 중간상단의 MEASURE 아이콘을 터치 2. "REF/KER 측정 MODE 화면"의 우측하단의 프린터 아이콘을 터치. 3. OP Basic Operation 화면 진입(OP 홈 화면에서 Basic Operation 터치) 4. OP 키보드의 LOAD 버튼 터치 5. OP Basic Operation 화면 좌측상단 LOAD DATA의 RK 버튼 터치 | H33: "REF/KER 측정 MODE 화면" 좌측상단 차트번호와 OP Basic Operation 화면 좌측상단 LOAD DATA의 차트번호 비교결과, "REF/KER 측정 MODE 화면" 차트번호가 1이 더 큰지 확인
G34: 1. OP Basic Operation 화면 좌측상단 LOAD DATA의 차트번호 터치 | H34: "REF/KER 측정 MODE 화면"의 중간단의 좌우 R, L 데이터 목록과 OP Basic Operation 화면 상단중간 데이터 비교결과, S(SPH), C(CYLINDER), A(TBD)의 수치가 일치 상태확인(TBD. STEP 디옵터 설정 의존성 확인)
F35: 테스트대상 구성 (장비 대수, S/W Version): - HRK-9000A (1대, 1.01.01A) 테스트환경 구성 : - AP(2.4GHz Band) 1대 - HDR-9000 1대 | G35: 1. AP 연결 및 인증 확인(HRK-001) 2. Server 연결 확인(HRK-002, HDR에 연결) 3. SETUP MODE 화면으로 진입(홈 화면 우측 하단 톱니바퀴 아이콘 터치) 4. SETUP MODE 화면-2 페이지-WIFI 탭으로 이동 5. TRANSFER TYPE를 Auto로 설정. 6. "REF/KER 측정 MODE 화면"으로 이동(SETUP MODE 화면에서 좌측상단 홈 아이콘 터치) | H35: "REF/KER 측정 MODE 화면" 시현확인 | I35: 전송 모드는 수동/자동 각각 설정하여 테스트 진행 측정 모드는 모드별로 테스트 진행 Server는 최소 1개, 최대 4개 늘려가면서 테스트 진행 | J35: 1. HDR / 1) 1대 / 불 2) 2대 / 2. HIIS / 3. MATE / | K35: -. HRK-9000A CCD 타입은 AP끊었을 시, 아이콘 갱신이 다소 오래걸림(Ver26) -. AP 재부팅 시, HDR에서 HRK와 자동 연결이 안되고, HRK에서 재시도를 하면 연결됨
G36: 1. 모델아이 장착 2. 조이스틱 수동조작하여 모델아이의 눈동자를 화면 위치로 대략적 배치 3. OP 홈 화면 진입(OP Basic Operation 화면에서 좌측상단 홈 아이콘 터치) 4. OP QC Settings 화면 진입(OP 홈 화면에서 Shift+MENU 터치) 5. OP QC Settings 화면의 "Commnunication 탭"의 Connection 항목을 OFF로 터치. 6. OP QC Settings 화면의 OK 터치 | H36: "REF/KER 측정 MODE 화면"에서 우측상단에서 *HDR 아이콘(미연결상태) 확인. 범례 *HDR 아이콘(미연결상태) : 회색톤 아이콘 표기, 좌상단심볼 X 파란색으로 표기
G37: 1. OP QC Settings 화면 진입(OP 홈 화면에서 Shift+MENU 터치) 2. OP QC Settings 화면의 "Commnunication 탭"의 Connection 항목을 ON로 터치. 3. OP QC Settings 화면의 OK 터치 | H37: OP 홈 화면 시현확인
G38: 1. "REF/KER 측정 MODE 화면"의 중간상단의 MEASURE 아이콘을 터치 2. "REF/KER 측정 MODE 화면"의 우측하단의 프린터 아이콘을 터치. | H38: HDR network connect 모달 시현확인
G39: 1. "REF/KER 측정 MODE 화면"의 HDR network connect 모달에서 "HDR 재연결 시도 아이콘" 터치 | H39: "REF/KER 측정 MODE 화면"의 HDR network connect 모달에서 "HDR 재연결 시도 아이콘" 이 "HDR 연결완료 아이콘" 으로 변경 확인
G40: 1. "REF/KER 측정 MODE 화면"의 HDR network connect 모달에서 OK 터치 2. OP Basic Operation 화면 진입(OP 홈 화면에서 Basic Operation 터치) 3. OP 키보드의 LOAD 버튼 터치 4. OP Basic Operation 화면 좌측상단 LOAD DATA의 RK 버튼 터치 | H40: "REF/KER 측정 MODE 화면" 좌측상단 차트번호와 OP Basic Operation 화면 좌측상단 LOAD DATA의 차트번호 비교결과, "REF/KER 측정 MODE 화면" 차트번호가 2차이 이상 임을 확인 (데이터 안들어온 것으로 판단) TBD. 정상루틴인 건지 문제인건지 확인필요
...

Sheet Test Runs (2)
A1: 구분 | B1: 날짜 | C1: ID | D1: 테스트 항목 | E1: 기대결과 | F1: 문제점 | G1: 문제점 절차 | H1: 첨부파일(사진)
A2: 문제점 관리 | B2: 46113 | C2: HRK-003 | D2: 측정 Data 전송 | E2: Data 전송이 잘 되어야 함 | F2: -. HIIS 데이터 전송 값 삭제가 안됨 | G2: -. HRK->HIIS->Refraction 데이터 삭제 안됨 (검토)
A3: 문제점 관리 | B3: 46113 | C3: HRK-010 | D3: =IFERROR(INDEX('HRK 테스트'!B:B,MATCH(TRIM(CLEAN(C3)),'HRK 테스트'!A:A,0)), IFERROR(INDEX('HLM 테스트'!B:B,MATCH(TRIM(CLEAN(C3)),'HLM 테스트'!A:A,0)), IFERROR(INDEX('HTR 테스트'!B:B,MATCH(TRIM(CLEAN(C3)),'HTR 테스트'!A:A,0)), IFERROR(INDEX('HDR 테스트'!B:B,MATCH(TRIM(CLEAN(C3)),'HDR 테스트'!A:A,0)), IFERROR(INDEX('HDC 테스트'!B:B,MATCH(TRIM(CLEAN(C3)),'HDC 테스트'!A:A,0)),""))))) -> Server 재연결 시 복구 | E3: =IFERROR(INDEX('HRK 테스트'!D:D,MATCH(TRIM(CLEAN(C3)),'HRK 테스트'!A:A,0)), IFERROR(INDEX('HLM 테스트'!D:D,MATCH(TRIM(CLEAN(C3)),'HLM 테스트'!A:A,0)), IFERROR(INDEX('HTR 테스트'!D:D,MATCH(TRIM(CLEAN(C3)),'HTR 테스트'!A:A,0)), IFERROR(INDEX('HDR 테스트'!D:D,MATCH(TRIM(CLEAN(C3)),'HDR 테스트'!A:A,0)), IFERROR(INDEX('HDC 테스트'!D:D,MATCH(TRIM(CLEAN(C3)),'HDC 테스트'!A:A,0)),""))))) -> 1. Server 접속상태 표시 2. Server와의 접속상태를 갱신하고, 데이터 전송 성공 3. 데이터 전송 실패시 에러메세지 확인( DR(Server)와 끊어짐 상태 표시 또는 전송실패 표시 ) 4. 실패 이후 재전송 성공 | F3: -. AP 재부팅 시 재 연결 안됨 | G3: -. AP 재부팅 시, HDR에서 HRK와 자동 연결이 안되고, HRK에서 재시도를 하면 연결됨
A4: 문제점 관리 | B4: 46113 | C4: HRK-011 | D4: =IFERROR(INDEX('HRK 테스트'!B:B,MATCH(TRIM(CLEAN(C4)),'HRK 테스트'!A:A,0)), IFERROR(INDEX('HLM 테스트'!B:B,MATCH(TRIM(CLEAN(C4)),'HLM 테스트'!A:A,0)), IFERROR(INDEX('HTR 테스트'!B:B,MATCH(TRIM(CLEAN(C4)),'HTR 테스트'!A:A,0)), IFERROR(INDEX('HDR 테스트'!B:B,MATCH(TRIM(CLEAN(C4)),'HDR 테스트'!A:A,0)), IFERROR(INDEX('HDC 테스트'!B:B,MATCH(TRIM(CLEAN(C4)),'HDC 테스트'!A:A,0)),""))))) -> 장비 재부팅 시 복구 | E4: =IFERROR(INDEX('HRK 테스트'!D:D,MATCH(TRIM(CLEAN(C4)),'HRK 테스트'!A:A,0)), IFERROR(INDEX('HLM 테스트'!D:D,MATCH(TRIM(CLEAN(C4)),'HLM 테스트'!A:A,0)), IFERROR(INDEX('HTR 테스트'!D:D,MATCH(TRIM(CLEAN(C4)),'HTR 테스트'!A:A,0)), IFERROR(INDEX('HDR 테스트'!D:D,MATCH(TRIM(CLEAN(C4)),'HDR 테스트'!A:A,0)), IFERROR(INDEX('HDC 테스트'!D:D,MATCH(TRIM(CLEAN(C4)),'HDC 테스트'!A:A,0)),""))))) -> 1. 데이터 전송 성공 2. 데이터 전송 실패시 에러메세지 확인( DR(Server)와 끊어짐 상태 표시 또는 전송실패 표시 ) 3. 실패 이후 재전송 성공 | F4: -. 양산버전이 재부팅 시 연결안됨 | G4: -. 제품 1분정도 OFF 후 재부팅 시 연결X (양산품, CCD 변경품으로 테스트) - 제품별 연결성 차이 검토
A5: 문제점 관리 | B5: 46148 | C5: HRK-001 | D5: =IFERROR(INDEX('HRK 테스트'!B:B,MATCH(TRIM(CLEAN(C5)),'HRK 테스트'!A:A,0)), IFERROR(INDEX('HLM 테스트'!B:B,MATCH(TRIM(CLEAN(C5)),'HLM 테스트'!A:A,0)), IFERROR(INDEX('HTR 테스트'!B:B,MATCH(TRIM(CLEAN(C5)),'HTR 테스트'!A:A,0)), IFERROR(INDEX('HDR 테스트'!B:B,MATCH(TRIM(CLEAN(C5)),'HDR 테스트'!A:A,0)), IFERROR(INDEX('HDC 테스트'!B:B,MATCH(TRIM(CLEAN(C5)),'HDC 테스트'!A:A,0)),""))))) -> AP 연결 및 인증 확인 | E5: =IFERROR(INDEX('HRK 테스트'!D:D,MATCH(TRIM(CLEAN(C5)),'HRK 테스트'!A:A,0)), IFERROR(INDEX('HLM 테스트'!D:D,MATCH(TRIM(CLEAN(C5)),'HLM 테스트'!A:A,0)), IFERROR(INDEX('HTR 테스트'!D:D,MATCH(TRIM(CLEAN(C5)),'HTR 테스트'!A:A,0)), IFERROR(INDEX('HDR 테스트'!D:D,MATCH(TRIM(CLEAN(C5)),'HDR 테스트'!A:A,0)), IFERROR(INDEX('HDC 테스트'!D:D,MATCH(TRIM(CLEAN(C5)),'HDC 테스트'!A:A,0)),""))))) -> 1. 연결 가능한 AP 목록 (SSID/RSSI 순서) 2. AP 연결 성공 3. AP 인증 성공 | F5: =SUBSTITUTE(SUBSTITUTE(IFERROR(INDEX('HRK 테스트'!D:D,MATCH(TRIM(CLEAN(C5)),'HRK 테스트'!A:A,0)), IFERROR(INDEX('HLM 테스트'!D:D,MATCH(TRIM(CLEAN(C5)),'HLM 테스트'!A:A,0)), IFERROR(INDEX('HTR 테스트'!D:D,MATCH(TRIM(CLEAN(C5)),'HTR 테스트'!A:A,0)), IFERROR(INDEX('HDR 테스트'!D:D,MATCH(TRIM(CLEAN(C5)),'HDR 테스트'!A:A,0)), IFERROR(INDEX('HDC 테스트'!D:D,MATCH(TRIM(CLEAN(C5)),'HDC 테스트'!A:A,0)),""))))),CHAR(13)&CHAR(10),CHAR(10)),CHAR(13),CHAR(10)) -> 1. 연결 가능한 AP 목록 (SSID/RSSI 순서) 2. AP 연결 성공 3. AP 인증 성공
A6: 시나리오 & TC 정합성 협의사항(특이사항) | C6: HRK-002 | F6: =IFERROR(INDEX('Test Cases (2)'!K:K,MATCH(TRIM(CLEAN(C6)),'Test Cases (2)'!A:A,0)),"") -> 0
A7: 시나리오 & TC 정합성 협의사항(특이사항) | C7: HRK-003 | F7: =IFERROR(INDEX('Test Cases (2)'!K:K,MATCH(TRIM(CLEAN(C7)),'Test Cases (2)'!A:A,0)),"") -> 0
A8: 시나리오 & TC 정합성 협의사항(특이사항) | C8: HRK-004 | F8: =IFERROR(INDEX('Test Cases (2)'!K:K,MATCH(TRIM(CLEAN(C8)),'Test Cases (2)'!A:A,0)),"") -> 0
A9: 시나리오 & TC 정합성 협의사항(특이사항) | C9: HRK-005 | F9: =IFERROR(INDEX('Test Cases (2)'!K:K,MATCH(TRIM(CLEAN(C9)),'Test Cases (2)'!A:A,0)),"") -> 0
A10: 시나리오 & TC 정합성 협의사항(특이사항) | C10: HRK-006 | F10: =IFERROR(INDEX('Test Cases (2)'!K:K,MATCH(TRIM(CLEAN(C10)),'Test Cases (2)'!A:A,0)),"") -> 0
A11: 시나리오 & TC 정합성 협의사항(특이사항) | C11: HRK-007 | F11: =IFERROR(INDEX('Test Cases (2)'!K:K,MATCH(TRIM(CLEAN(C11)),'Test Cases (2)'!A:A,0)),"") -> 0
A12: 시나리오 & TC 정합성 협의사항(특이사항) | C12: HRK-008 | F12: =IFERROR(INDEX('Test Cases (2)'!K:K,MATCH(TRIM(CLEAN(C12)),'Test Cases (2)'!A:A,0)),"") -> 0
A13: 시나리오 & TC 정합성 협의사항(특이사항) | C13: HRK-009 | F13: =IFERROR(INDEX('Test Cases (2)'!K:K,MATCH(TRIM(CLEAN(C13)),'Test Cases (2)'!A:A,0)),"") -> 0
A14: 시나리오 & TC 정합성 협의사항(특이사항) | C14: HRK-010 | F14: =IFERROR(INDEX('Test Cases (2)'!K:K,MATCH(TRIM(CLEAN(C14)),'Test Cases (2)'!A:A,0)),"") -> -. HRK-9000A CCD 타입은 AP끊었을 시, 아이콘 갱신이 다소 오래걸림(Ver26) -. AP 재부팅 시, HDR에서 HRK와 자동 연결이 안되고, HRK에서 재시도를 하면 연결됨
A15: 시나리오 & TC 정합성 협의사항(특이사항) | C15: HRK-011 | F15: =IFERROR(INDEX('Test Cases (2)'!K:K,MATCH(TRIM(CLEAN(C15)),'Test Cases (2)'!A:A,0)),"") -> 0
A16: 시나리오 & TC 정합성 협의사항(특이사항) | C16: HRK-012 | F16: =IFERROR(INDEX('Test Cases (2)'!K:K,MATCH(TRIM(CLEAN(C16)),'Test Cases (2)'!A:A,0)),"")

Sheet Test Releases (2)
A1: Test Release ID | B1: Upstream Release ID | C1: Test Run IDs | D1: Test Case IDs
A2: TEST_RELEASE_ID-HRK-9000A_1.01.01A | B2: 1.01.01A
A3: TEST_RELEASE_ID-
A4: TEST_RELEASE_ID-
A5: TEST_RELEASE_ID-
A6: TEST_RELEASE_ID-
A7: TEST_RELEASE_ID-
A8: TEST_RELEASE_ID-
A9: TEST_RELEASE_ID-
A10: TEST_RELEASE_ID-
A11: TEST_RELEASE_ID-
A12: TEST_RELEASE_ID-
A13: TEST_RELEASE_ID-
A14: TEST_RELEASE_ID-
... A21: TEST_RELEASE_ID-
A26: Test Target Reference ID | B26: 모델명
A27: =CONCATENATE("TTRID-", B27) -> TTRID-HRK-9000A | B27: HRK-9000A
A28: =CONCATENATE("TTRID-", B28) -> TTRID-HLM-9000 | B28: HLM-9000
A29: =CONCATENATE("TTRID-", B29) -> TTRID-HTR 상세모델명(TBD) | B29: HTR 상세모델명(TBD)
A30: =CONCATENATE("TTRID-", B30) -> TTRID-HDR-9000_OP | B30: HDR-9000_OP
A31: =CONCATENATE("TTRID-", B31) -> TTRID-HDR-9000_JUNCTION_BOX | B31: HDR-9000_JUNCTION_BOX
A32: =CONCATENATE("TTRID-", B32) -> TTRID-HDR-9000_? | B32: HDR-9000_?
A33: =CONCATENATE("TTRID-", B33) -> TTRID-HDC-9100 | B33: HDC-9100
A40: Test Target ID | B40: 모델명 | C40: 대상 일련번호
A41: TTRID-HRK-9000A | B41: HRK-9000A | C41: 9HA09A24I0014
A42: TTRID-HLM-9000 | B42: HLM-9000 | C42: 9LM00024D0014
A43: TTRID-HTR 상세모델명(TBD) | B43: HTR 상세모델명(TBD) | C43: TBD
A44: TTRID-HDR-9000_OP | B44: HDR-9000_OP | C44: TBD
A45: TTRID-HDR-9000_JUNCTION_BOX | B45: HDR-9000_JUNCTION_BOX | C45: TBD
A46: TTRID-HDR-9000_? | B46: HDR-9000_? | C46: TBD
A47: TTRID-HDC-9100 | B47: HDC-9100 | C47: PP #1(관리번호 L-062)
A54: Test Environment ID | B54: 모델명 | C54: 대상 일련번호
B55: MR30G | C55: 2232318003141
B56: MR30G | C56: Wi-Fi Band 분리설정
B57: MR30G | C57: Wi-Fi Channel 설정
B58: MR30G | C58: Channel Bandwidth 설정
B59: MR30G | C59: Wi-Fi 규격 ( Mode ) 설정
B60: MR30G | C60: Wi-Fi Security
B61: Lens
B62: 모델아이
...

Sheet Test Report
A1: Test Report ID | B1: Test Release ID
A2: TEST_RELEASE_ID-HRK-9000A_1.01.01A | B2: TEST_RELEASE_ID-HRK-9000A_1.01.01A
A3: TEST_RELEASE_ID- | B3: TEST_RELEASE_ID-
A4: TEST_RELEASE_ID- | B4: TEST_RELEASE_ID-
A5: TEST_RELEASE_ID- | B5: TEST_RELEASE_ID-
A6: TEST_RELEASE_ID- | B6: TEST_RELEASE_ID-
A7: TEST_RELEASE_ID- | B7: TEST_RELEASE_ID-
A8: TEST_RELEASE_ID- | B8: TEST_RELEASE_ID-
A9: TEST_RELEASE_ID- | B9: TEST_RELEASE_ID-
A10: TEST_RELEASE_ID- | B10: TEST_RELEASE_ID-
A11: TEST_RELEASE_ID- | B11: TEST_RELEASE_ID-
A12: TEST_RELEASE_ID- | B12: TEST_RELEASE_ID-
... A21: TEST_RELEASE_ID- | B21: TEST_RELEASE_ID-

Sheet Connectivity Room Routers (2)
A1: 제조사 | B1: 제품별칭 | C1: 모델명 | D1: 일련번호 | E1: Purpose of Use | F1: Input | G1: Default SSID(5GHz) | H1: Default SSID(2.4GHz) | I1: Default Password | J1: Installed Location(Last Location) | K1: Installed Date | L1: Sticker Labeled | M1: First Connection Tested | N1: 비고
A2: ASUS | B2: Wireless Dual Band WiFi 6 Router | C2: RT-AX1800S V2 | D2: W1IG758026888HD | E2: 미국 현지 네트워크 환경 모의 | F2: 12V, 1.5A | G2: ASUS_F6 | H2: ASUS_F6 | I2: 11708421 | J2: /6th/Connectivity Room/4th_rack_black/TODO | K2: 46148 | L2: TODO | M2: TODO | N2: Quick Wi-Fi Connect QR Code
A3: NETGEAR | B3: Nighthawk AXE11000 Tri-Band WiFi 6E Router | C3: RAXE500 | D3: 6TA53B7HD00EE | E3: 미국 현지 네트워크 환경 모의 | F3: 19V, 3.16A | G3: NETGEAR11 | H3: NETGEAR11 | I3: basicbird145 | J3: /6th/Connectivity Room/4th_rack_black/TODO | K3: 46148 | L3: TODO | M3: TODO
A4: NETGEAR | B4: AC1200 WiFi Router | C4: R6120 | D4: 64E226B3A225B | E4: 미국 현지 네트워크 환경 모의 | F4: 12V, 1.5A | G4: NETGEAR56 | H4: NETGEAR56 | I4: fuzzyphoenix865 | J4: /6th/Connectivity Room/4th_rack_black/TODO | K4: 46148 | L4: TODO | M4: TODO
A5: Tenda | B5: Dual-Band Gigabit Wi-Fi 6 Router | C5: RX2 Pro | D5: ED681011551001002 V1.0 | E5: 미국 현지 네트워크 환경 모의 | F5: 12V, 1A | G5: Tenda_EFFAA0 | H5: Tenda_EFFAA0 | I5: 14796449 | J5: /6th/Connectivity Room/4th_rack_black/TODO | K5: 46148 | L5: TODO | M5: TODO
A6: TP-link | B6: AX1800 Gigabit Wi-Fi 6 Router | C6: Archer AX1800(USW) Ver:4.6 | D6: Y233061F00520 | E6: 미국 현지 네트워크 환경 모의 | F6: 12V, 1.5A | G6: TB-Link_A2B2_5G | H6: TB-Link_A2B2 | I6: 38042966 | J6: /6th/Connectivity Room/4th_rack_black/TODO | K6: 46148 | L6: TODO | M6: TODO | N6: JOIN PRESET Wi-Fi QR CODE Default Setup Link : http://tplinkwifi.net
A7: TP-link | B7: AX1500 Wi-Fi 6 Router | C7: Archer AX10 | D7: Y258005000560 | E7: 미국 현지 네트워크 환경 모의 | F7: 12V, 1A | G7: TB-Link_35E8_5G | H7: TB-Link_35E8 | I7: 24795388 | J7: /6th/Connectivity Room/4th_rack_black/TODO | K7: 46148 | L7: TODO | M7: TODO
A8: MERCUSYS | B8: AC1200 Wireless Dual Band Gigabit Router | C8: MR30G | D8: 2232318003141 | E8: 대한민국 현지 네트워크 환경 모의 | F8: 9V, 0.85A | G8: MERCUSYS_BA30_5G | H8: MERCUSYS_BA30 | I8: 5939373 | J8: /6th/Connectivity Room/3rd_rack_white_1/TODO | L8: TODO | M8: TODO | N8: TODO

Sheet 테스트 환경
A1: Router WiFi 체크리스트
A2: ID | B2: 체크 항목 | C2: Study & TBD | D2: Examples to Avoid | E2: Actual Steps to Apply | F2: Actual Applied | G2: Remark & Questions
A3: 1 | B3: Wi-Fi Band 분리설정 | C3: TBD 2.4GHz : xxxxx (_2_4G 접미사 붙이면 명시적) 5GHz : xxxxx_5G | E3: http://{router_ip} http://192.168.0.1 또는 http://192.168.1.1 공유기 하단 라벨 참고 Smart Connect / Band Steering | F3: OFF or SSID 분리표기확인
A4: 2 | B4: Wi-Fi Channel 설정 | C4: TBD 2.4GHz : 1, 6 , 11 을 실무적으로 추천 5GHz : 36, 40, 44, 48 채널고정 (DFS 채널 회피) | D4: Channel: Auto | E4: Wireless / Channel | F4: 2.4GHz Channel → 1 / 6 / 11 5GHz Channel → 36 / 40 / 44 / 48
